Workbook

Sheet BIData
A2: =IFERROR(IF(0=LEN(ReferenceData!$A$2),"",ReferenceData!$A$2),"") -> Description | B2: =IFERROR(IF(0=LEN(ReferenceData!$B$2),"",ReferenceData!$B$2),"") -> Ticker | C2: =IFERROR(IF(0=LEN(ReferenceData!$C$2),"",ReferenceData!$C$2),"") -> Field ID | D2: =IFERROR(IF(0=LEN(ReferenceData!$D$2),"",ReferenceData!$D$2),"") -> Field Mnemonic | E2: =IFERROR(IF(0=LEN(ReferenceData!$E$2),"",ReferenceData!$E$2),"") -> Data State | F2: =IFERROR(IF(0=LEN(ReferenceData!$AG$2),"",ReferenceData!$AG$2),"") -> 2012 S1 | G2: =IFERROR(IF(0=LEN(ReferenceData!$AF$2),"",ReferenceData!$AF$2),"") -> 2012 S2 | H2: =IFERROR(IF(0=LEN(ReferenceData!$AE$2),"",ReferenceData!$AE$2),"") -> 2013 S1 | I2: =IFERROR(IF(0=LEN(ReferenceData!$AD$2),"",ReferenceData!$AD$2),"") -> 2013 S2 | J2: =IFERROR(IF(0=LEN(ReferenceData!$AC$2),"",ReferenceData!$AC$2),"") -> 2014 S1 | K2: =IFERROR(IF(0=LEN(ReferenceData!$AB$2),"",ReferenceData!$AB$2),"") -> 2014 S2 | L2: =IFERROR(IF(0=LEN(ReferenceData!$AA$2),"",ReferenceData!$AA$2),"") -> 2015 S1 | M2: =IFERROR(IF(0=LEN(ReferenceData!$Z$2),"",ReferenceData!$Z$2),"") -> 2015 S2 | N2: =IFERROR(IF(0=LEN(ReferenceData!$Y$2),"",ReferenceData!$Y$2),"") -> 2016 S1 | O2: =IFERROR(IF(0=LEN(ReferenceData!$X$2),"",ReferenceData!$X$2),"") -> 2016 S2 | P2: =IFERROR(IF(0=LEN(ReferenceData!$W$2),"",ReferenceData!$W$2),"") -> 2017 S1 | Q2: =IFERROR(IF(0=LEN(ReferenceData!$V$2),"",ReferenceData!$V$2),"") -> 2017 S2 | R2: =IFERROR(IF(0=LEN(ReferenceData!$U$2),"",ReferenceData!$U$2),"") -> 2018 S1 | S2: =IFERROR(IF(0=LEN(ReferenceData!$T$2),"",ReferenceData!$T$2),"") -> 2018 S2 | T2: =IFERROR(IF(0=LEN(ReferenceData!$S$2),"",ReferenceData!$S$2),"") -> 2019 S1 | U2: =IFERROR(IF(0=LEN(ReferenceData!$R$2),"",ReferenceData!$R$2),"") -> 2019 S2 | V2: =IFERROR(IF(0=LEN(ReferenceData!$Q$2),"",ReferenceData!$Q$2),"") -> 2020 S1 | W2: =IFERROR(IF(0=LEN(ReferenceData!$P$2),"",ReferenceData!$P$2),"") -> 2020 S2 | X2: =IFERROR(IF(0=LEN(ReferenceData!$O$2),"",ReferenceData!$O$2),"") -> 2021 S1 | Y2: =IFERROR(IF(0=LEN(ReferenceData!$N$2),"",ReferenceData!$N$2),"") -> 2021 S2 | Z2: =IFERROR(IF(0=LEN(ReferenceData!$M$2),"",ReferenceData!$M$2),"") -> 2022 S1 | AA2: =IFERROR(IF(0=LEN(ReferenceData!$L$2),"",ReferenceData!$L$2),"") -> 2022 S2 | AB2: =IFERROR(IF(0=LEN(ReferenceData!$K$2),"",ReferenceData!$K$2),"") -> 2023 S1 | AC2: =IFERROR(IF(0=LEN(ReferenceData!$J$2),"",ReferenceData!$J$2),"") -> 2023 S2 | AD2: =IFERROR(IF(0=LEN(ReferenceData!$I$2),"",ReferenceData!$I$2),"") -> 2024 S1 | AE2: =IFERROR(IF(0=LEN(ReferenceData!$H$2),"",ReferenceData!$H$2),"") -> 2024 S2 | AF2: =IFERROR(IF(0=LEN(ReferenceData!$G$2),"",ReferenceData!$G$2),"") -> 2025 S1 | AG2: =IFERROR(IF(0=LEN(ReferenceData!$F$2),"",ReferenceData!$F$2),"") -> 2025 S2
A3: =IFERROR(IF(0=LEN(ReferenceData!$A$3),"",ReferenceData!$A$3),"") -> ETFs as % Of Total Fund Assets (MF & ETF) | B3: =IFERROR(IF(0=LEN(ReferenceData!$B$3),"",ReferenceData!$B$3),"") | C3: =IFERROR(IF(0=LEN(ReferenceData!$C$3),"",ReferenceData!$C$3),"") | D3: =IFERROR(IF(0=LEN(ReferenceData!$D$3),"",ReferenceData!$D$3),"") | E3: =IFERROR(IF(0=LEN(ReferenceData!$E$3),"",ReferenceData!$E$3),"") -> Expression | F3: =IFERROR(IF(0=LEN(ReferenceData!$AG$3),"",ReferenceData!$AG$3),"") -> 13.217836 | G3: =IFERROR(IF(0=LEN(ReferenceData!$AF$3),"",ReferenceData!$AF$3),"") -> 13.609661 | H3: =IFERROR(IF(0=LEN(ReferenceData!$AE$3),"",ReferenceData!$AE$3),"") -> 13.716417 | I3: =IFERROR(IF(0=LEN(ReferenceData!$AD$3),"",ReferenceData!$AD$3),"") -> 14.260533 | J3: =IFERROR(IF(0=LEN(ReferenceData!$AC$3),"",ReferenceData!$AC$3),"") -> 14.370747 | K3: =IFERROR(IF(0=LEN(ReferenceData!$AB$3),"",ReferenceData!$AB$3),"") -> 15.224923 | L3: =IFERROR(IF(0=LEN(ReferenceData!$AA$3),"",ReferenceData!$AA$3),"") -> 15.785424 | M3: =IFERROR(IF(0=LEN(ReferenceData!$Z$3),"",ReferenceData!$Z$3),"") -> 16.102875 | N3: =IFERROR(IF(0=LEN(ReferenceData!$Y$3),"",ReferenceData!$Y$3),"") -> 16.673301 | O3: =IFERROR(IF(0=LEN(ReferenceData!$X$3),"",ReferenceData!$X$3),"") -> 18.051022 | P3: =IFERROR(IF(0=LEN(ReferenceData!$W$3),"",ReferenceData!$W$3),"") -> 18.871804 | Q3: =IFERROR(IF(0=LEN(ReferenceData!$V$3),"",ReferenceData!$V$3),"") -> 20.09652 | R3: =IFERROR(IF(0=LEN(ReferenceData!$U$3),"",ReferenceData!$U$3),"") -> 20.237705 | S3: =IFERROR(IF(0=LEN(ReferenceData!$T$3),"",ReferenceData!$T$3),"") -> 21.149005 | T3: =IFERROR(IF(0=LEN(ReferenceData!$S$3),"",ReferenceData!$S$3),"") -> 21.635465 | U3: =IFERROR(IF(0=LEN(ReferenceData!$R$3),"",ReferenceData!$R$3),"") -> 22.093074 | V3: =IFERROR(IF(0=LEN(ReferenceData!$Q$3),"",ReferenceData!$Q$3),"") -> 22.528549 | W3: =IFERROR(IF(0=LEN(ReferenceData!$P$3),"",ReferenceData!$P$3),"") -> 23.858694 | X3: =IFERROR(IF(0=LEN(ReferenceData!$O$3),"",ReferenceData!$O$3),"") -> 25.120084 | Y3: =IFERROR(IF(0=LEN(ReferenceData!$N$3),"",ReferenceData!$N$3),"") -> 26.221668 | Z3: =IFERROR(IF(0=LEN(ReferenceData!$M$3),"",ReferenceData!$M$3),"") -> 27.625432 | AA3: =IFERROR(IF(0=LEN(ReferenceData!$L$3),"",ReferenceData!$L$3),"") -> 29.068671 | AB3: =IFERROR(IF(0=LEN(ReferenceData!$K$3),"",ReferenceData!$K$3),"") -> 29.827034 | AC3: =IFERROR(IF(0=LEN(ReferenceData!$J$3),"",ReferenceData!$J$3),"") -> 31.031894 | AD3: =IFERROR(IF(0=LEN(ReferenceData!$I$3),"",ReferenceData!$I$3),"") -> 32.208543 | AE3: =IFERROR(IF(0=LEN(ReferenceData!$H$3),"",ReferenceData!$H$3),"") -> 34.105675 | AF3: =IFERROR(IF(0=LEN(ReferenceData!$G$3),"",ReferenceData!$G$3),"") -> 35.358068 | AG3: =IFERROR(IF(0=LEN(ReferenceData!$F$3),"",ReferenceData!$F$3),"") -> 37.078442
A4: =IFERROR(IF(0=LEN(ReferenceData!$A$4),"",ReferenceData!$A$4),"") -> ETFs as % Of Equity Fund Assets (MF & ETF) | B4: =IFERROR(IF(0=LEN(ReferenceData!$B$4),"",ReferenceData!$B$4),"") | C4: =IFERROR(IF(0=LEN(ReferenceData!$C$4),"",ReferenceData!$C$4),"") | D4: =IFERROR(IF(0=LEN(ReferenceData!$D$4),"",ReferenceData!$D$4),"") | E4: =IFERROR(IF(0=LEN(ReferenceData!$E$4),"",ReferenceData!$E$4),"") -> Expression | F4: =IFERROR(IF(0=LEN(ReferenceData!$AG$4),"",ReferenceData!$AG$4),"") -> 16.258832 | G4: =IFERROR(IF(0=LEN(ReferenceData!$AF$4),"",ReferenceData!$AF$4),"") -> 16.974729 | H4: =IFERROR(IF(0=LEN(ReferenceData!$AE$4),"",ReferenceData!$AE$4),"") -> 17.331619 | I4: =IFERROR(IF(0=LEN(ReferenceData!$AD$4),"",ReferenceData!$AD$4),"") -> 17.835893 | J4: =IFERROR(IF(0=LEN(ReferenceData!$AC$4),"",ReferenceData!$AC$4),"") -> 17.945907 | K4: =IFERROR(IF(0=LEN(ReferenceData!$AB$4),"",ReferenceData!$AB$4),"") -> 18.957734 | L4: =IFERROR(IF(0=LEN(ReferenceData!$AA$4),"",ReferenceData!$AA$4),"") -> 19.550153 | M4: =IFERROR(IF(0=LEN(ReferenceData!$Z$4),"",ReferenceData!$Z$4),"") -> 19.886805 | N4: =IFERROR(IF(0=LEN(ReferenceData!$Y$4),"",ReferenceData!$Y$4),"") -> 20.249502 | O4: =IFERROR(IF(0=LEN(ReferenceData!$X$4),"",ReferenceData!$X$4),"") -> 22.073154 | P4: =IFERROR(IF(0=LEN(ReferenceData!$W$4),"",ReferenceData!$W$4),"") -> 22.733653 | Q4: =IFERROR(IF(0=LEN(ReferenceData!$V$4),"",ReferenceData!$V$4),"") -> 24.075207 | R4: =IFERROR(IF(0=LEN(ReferenceData!$U$4),"",ReferenceData!$U$4),"") -> 24.1134 | S4: =IFERROR(IF(0=LEN(ReferenceData!$T$4),"",ReferenceData!$T$4),"") -> 25.357024 | T4: =IFERROR(IF(0=LEN(ReferenceData!$S$4),"",ReferenceData!$S$4),"") -> 25.510193 | U4: =IFERROR(IF(0=LEN(ReferenceData!$R$4),"",ReferenceData!$R$4),"") -> 25.914774 | V4: =IFERROR(IF(0=LEN(ReferenceData!$Q$4),"",ReferenceData!$Q$4),"") -> 25.835629 | W4: =IFERROR(IF(0=LEN(ReferenceData!$P$4),"",ReferenceData!$P$4),"") -> 27.335587 | X4: =IFERROR(IF(0=LEN(ReferenceData!$O$4),"",ReferenceData!$O$4),"") -> 28.927924 | Y4: =IFERROR(IF(0=LEN(ReferenceData!$N$4),"",ReferenceData!$N$4),"") -> 30.197149 | Z4: =IFERROR(IF(0=LEN(ReferenceData!$M$4),"",ReferenceData!$M$4),"") -> 31.845603 | AA4: =IFERROR(IF(0=LEN(ReferenceData!$L$4),"",ReferenceData!$L$4),"") -> 32.998992 | AB4: =IFERROR(IF(0=LEN(ReferenceData!$K$4),"",ReferenceData!$K$4),"") -> 33.307887 | AC4: =IFERROR(IF(0=LEN(ReferenceData!$J$4),"",ReferenceData!$J$4),"") -> 34.533582 | AD4: =IFERROR(IF(0=LEN(ReferenceData!$I$4),"",ReferenceData!$I$4),"") -> 35.565675 | AE4: =IFERROR(IF(0=LEN(ReferenceData!$H$4),"",ReferenceData!$H$4),"") -> 37.546944 | AF4: =IFERROR(IF(0=LEN(ReferenceData!$G$4),"",ReferenceData!$G$4),"") -> 38.517793 | AG4: =IFERROR(IF(0=LEN(ReferenceData!$F$4),"",ReferenceData!$F$4),"") -> 40.405625
A5: =IFERROR(IF(0=LEN(ReferenceData!$A$5),"",ReferenceData!$A$5),"") -> ETFs as % Of Bond Fund Assets (MF & ETF) | B5: =IFERROR(IF(0=LEN(ReferenceData!$B$5),"",ReferenceData!$B$5),"") | C5: =IFERROR(IF(0=LEN(ReferenceData!$C$5),"",ReferenceData!$C$5),"") | D5: =IFERROR(IF(0=LEN(ReferenceData!$D$5),"",ReferenceData!$D$5),"") | E5: =IFERROR(IF(0=LEN(ReferenceData!$E$5),"",ReferenceData!$E$5),"") -> Expression | F5: =IFERROR(IF(0=LEN(ReferenceData!$AG$5),"",ReferenceData!$AG$5),"") -> 8.1925826 | G5: =IFERROR(IF(0=LEN(ReferenceData!$AF$5),"",ReferenceData!$AF$5),"") -> 7.923056 | H5: =IFERROR(IF(0=LEN(ReferenceData!$AE$5),"",ReferenceData!$AE$5),"") -> 8.2138024 | I5: =IFERROR(IF(0=LEN(ReferenceData!$AD$5),"",ReferenceData!$AD$5),"") -> 8.2122219 | J5: =IFERROR(IF(0=LEN(ReferenceData!$AC$5),"",ReferenceData!$AC$5),"") -> 8.4660436 | K5: =IFERROR(IF(0=LEN(ReferenceData!$AB$5),"",ReferenceData!$AB$5),"") -> 9.2535089 | L5: =IFERROR(IF(0=LEN(ReferenceData!$AA$5),"",ReferenceData!$AA$5),"") -> 9.6919105 | M5: =IFERROR(IF(0=LEN(ReferenceData!$Z$5),"",ReferenceData!$Z$5),"") -> 10.622748 | N5: =IFERROR(IF(0=LEN(ReferenceData!$Y$5),"",ReferenceData!$Y$5),"") -> 11.58322 | O5: =IFERROR(IF(0=LEN(ReferenceData!$X$5),"",ReferenceData!$X$5),"") -> 12.216942 | P5: =IFERROR(IF(0=LEN(ReferenceData!$W$5),"",ReferenceData!$W$5),"") -> 13.180263 | Q5: =IFERROR(IF(0=LEN(ReferenceData!$V$5),"",ReferenceData!$V$5),"") -> 13.824428 | R5: =IFERROR(IF(0=LEN(ReferenceData!$U$5),"",ReferenceData!$U$5),"") -> 14.188845 | S5: =IFERROR(IF(0=LEN(ReferenceData!$T$5),"",ReferenceData!$T$5),"") -> 15.259093 | T5: =IFERROR(IF(0=LEN(ReferenceData!$S$5),"",ReferenceData!$S$5),"") -> 16.049755 | U5: =IFERROR(IF(0=LEN(ReferenceData!$R$5),"",ReferenceData!$R$5),"") -> 16.415011 | V5: =IFERROR(IF(0=LEN(ReferenceData!$Q$5),"",ReferenceData!$Q$5),"") -> 17.96908 | W5: =IFERROR(IF(0=LEN(ReferenceData!$P$5),"",ReferenceData!$P$5),"") -> 18.192209 | X5: =IFERROR(IF(0=LEN(ReferenceData!$O$5),"",ReferenceData!$O$5),"") -> 18.516782 | Y5: =IFERROR(IF(0=LEN(ReferenceData!$N$5),"",ReferenceData!$N$5),"") -> 19.089849 | Z5: =IFERROR(IF(0=LEN(ReferenceData!$M$5),"",ReferenceData!$M$5),"") -> 20.9858 | AA5: =IFERROR(IF(0=LEN(ReferenceData!$L$5),"",ReferenceData!$L$5),"") -> 23.275326 | AB5: =IFERROR(IF(0=LEN(ReferenceData!$K$5),"",ReferenceData!$K$5),"") -> 24.507879 | AC5: =IFERROR(IF(0=LEN(ReferenceData!$J$5),"",ReferenceData!$J$5),"") -> 25.469519 | AD5: =IFERROR(IF(0=LEN(ReferenceData!$I$5),"",ReferenceData!$I$5),"") -> 26.128748 | AE5: =IFERROR(IF(0=LEN(ReferenceData!$H$5),"",ReferenceData!$H$5),"") -> 27.24881 | AF5: =IFERROR(IF(0=LEN(ReferenceData!$G$5),"",ReferenceData!$G$5),"") -> 28.762254 | AG5: =IFERROR(IF(0=LEN(ReferenceData!$F$5),"",ReferenceData!$F$5),"") -> 29.70135
A6: =IFERROR(IF(0=LEN(ReferenceData!$A$6),"",ReferenceData!$A$6),"") -> ETFs & Mutual Funds Passive % | B6: =IFERROR(IF(0=LEN(ReferenceData!$B$6),"",ReferenceData!$B$6),"") | C6: =IFERROR(IF(0=LEN(ReferenceData!$C$6),"",ReferenceData!$C$6),"") | D6: =IFERROR(IF(0=LEN(ReferenceData!$D$6),"",ReferenceData!$D$6),"") | E6: =IFERROR(IF(0=LEN(ReferenceData!$E$6),"",ReferenceData!$E$6),"") -> Heading | F6: =IFERROR(IF(0=LEN(ReferenceData!$AG$6),"",ReferenceData!$AG$6),"") | G6: =IFERROR(IF(0=LEN(ReferenceData!$AF$6),"",ReferenceData!$AF$6),"") | H6: =IFERROR(IF(0=LEN(ReferenceData!$AE$6),"",ReferenceData!$AE$6),"") | I6: =IFERROR(IF(0=LEN(ReferenceData!$AD$6),"",ReferenceData!$AD$6),"") | J6: =IFERROR(IF(0=LEN(ReferenceData!$AC$6),"",ReferenceData!$AC$6),"") | K6: =IFERROR(IF(0=LEN(ReferenceData!$AB$6),"",ReferenceData!$AB$6),"") | L6: =IFERROR(IF(0=LEN(ReferenceData!$AA$6),"",ReferenceData!$AA$6),"") | M6: =IFERROR(IF(0=LEN(ReferenceData!$Z$6),"",ReferenceData!$Z$6),"") | N6: =IFERROR(IF(0=LEN(ReferenceData!$Y$6),"",ReferenceData!$Y$6),"") | O6: =IFERROR(IF(0=LEN(ReferenceData!$X$6),"",ReferenceData!$X$6),"") | P6: =IFERROR(IF(0=LEN(ReferenceData!$W$6),"",ReferenceData!$W$6),"") | Q6: =IFERROR(IF(0=LEN(ReferenceData!$V$6),"",ReferenceData!$V$6),"") | R6: =IFERROR(IF(0=LEN(ReferenceData!$U$6),"",ReferenceData!$U$6),"") | S6: =IFERROR(IF(0=LEN(ReferenceData!$T$6),"",ReferenceData!$T$6),"") | T6: =IFERROR(IF(0=LEN(ReferenceData!$S$6),"",ReferenceData!$S$6),"") | U6: =IFERROR(IF(0=LEN(ReferenceData!$R$6),"",ReferenceData!$R$6),"") | V6: =IFERROR(IF(0=LEN(ReferenceData!$Q$6),"",ReferenceData!$Q$6),"") | W6: =IFERROR(IF(0=LEN(ReferenceData!$P$6),"",ReferenceData!$P$6),"") | X6: =IFERROR(IF(0=LEN(ReferenceData!$O$6),"",ReferenceData!$O$6),"") | Y6: =IFERROR(IF(0=LEN(ReferenceData!$N$6),"",ReferenceData!$N$6),"") | Z6: =IFERROR(IF(0=LEN(ReferenceData!$M$6),"",ReferenceData!$M$6),"") | AA6: =IFERROR(IF(0=LEN(ReferenceData!$L$6),"",ReferenceData!$L$6),"") | AB6: =IFERROR(IF(0=LEN(ReferenceData!$K$6),"",ReferenceData!$K$6),"") | AC6: =IFERROR(IF(0=LEN(ReferenceData!$J$6),"",ReferenceData!$J$6),"") | AD6: =IFERROR(IF(0=LEN(ReferenceData!$I$6),"",ReferenceData!$I$6),"") | AE6: =IFERROR(IF(0=LEN(ReferenceData!$H$6),"",ReferenceData!$H$6),"") | AF6: =IFERROR(IF(0=LEN(ReferenceData!$G$6),"",ReferenceData!$G$6),"") | AG6: =IFERROR(IF(0=LEN(ReferenceData!$F$6),"",ReferenceData!$F$6),"")
A7: =IFERROR(IF(0=LEN(ReferenceData!$A$7),"",ReferenceData!$A$7),"") -> Passive % Of All ETFs & Mutual Funds | B7: =IFERROR(IF(0=LEN(ReferenceData!$B$7),"",ReferenceData!$B$7),"") | C7: =IFERROR(IF(0=LEN(ReferenceData!$C$7),"",ReferenceData!$C$7),"") | D7: =IFERROR(IF(0=LEN(ReferenceData!$D$7),"",ReferenceData!$D$7),"") | E7: =IFERROR(IF(0=LEN(ReferenceData!$E$7),"",ReferenceData!$E$7),"") -> Expression | F7: =IFERROR(IF(0=LEN(ReferenceData!$AG$7),"",ReferenceData!$AG$7),"") -> 25.019725 | G7: =IFERROR(IF(0=LEN(ReferenceData!$AF$7),"",ReferenceData!$AF$7),"") -> 25.482054 | H7: =IFERROR(IF(0=LEN(ReferenceData!$AE$7),"",ReferenceData!$AE$7),"") -> 26.094993 | I7: =IFERROR(IF(0=LEN(ReferenceData!$AD$7),"",ReferenceData!$AD$7),"") -> 27.224338 | J7: =IFERROR(IF(0=LEN(ReferenceData!$AC$7),"",ReferenceData!$AC$7),"") -> 27.712089 | K7: =IFERROR(IF(0=LEN(ReferenceData!$AB$7),"",ReferenceData!$AB$7),"") -> 29.426864 | L7: =IFERROR(IF(0=LEN(ReferenceData!$AA$7),"",ReferenceData!$AA$7),"") -> 30.417419 | M7: =IFERROR(IF(0=LEN(ReferenceData!$Z$7),"",ReferenceData!$Z$7),"") -> 31.409682 | N7: =IFERROR(IF(0=LEN(ReferenceData!$Y$7),"",ReferenceData!$Y$7),"") -> 32.505148 | O7: =IFERROR(IF(0=LEN(ReferenceData!$X$7),"",ReferenceData!$X$7),"") -> 34.352407 | P7: =IFERROR(IF(0=LEN(ReferenceData!$W$7),"",ReferenceData!$W$7),"") -> 36.026475 | Q7: =IFERROR(IF(0=LEN(ReferenceData!$V$7),"",ReferenceData!$V$7),"") -> 37.751042 | R7: =IFERROR(IF(0=LEN(ReferenceData!$U$7),"",ReferenceData!$U$7),"") -> 38.2237 | S7: =IFERROR(IF(0=LEN(ReferenceData!$T$7),"",ReferenceData!$T$7),"") -> 39.842111 | T7: =IFERROR(IF(0=LEN(ReferenceData!$S$7),"",ReferenceData!$S$7),"") -> 41.186121 | U7: =IFERROR(IF(0=LEN(ReferenceData!$R$7),"",ReferenceData!$R$7),"") -> 41.605093 | V7: =IFERROR(IF(0=LEN(ReferenceData!$Q$7),"",ReferenceData!$Q$7),"") -> 41.780188 | W7: =IFERROR(IF(0=LEN(ReferenceData!$P$7),"",ReferenceData!$P$7),"") -> 42.791783 | X7: =IFERROR(IF(0=LEN(ReferenceData!$O$7),"",ReferenceData!$O$7),"") -> 43.878492 | Y7: =IFERROR(IF(0=LEN(ReferenceData!$N$7),"",ReferenceData!$N$7),"") -> 45.328458 | Z7: =IFERROR(IF(0=LEN(ReferenceData!$M$7),"",ReferenceData!$M$7),"") -> 46.40419 | AA7: =IFERROR(IF(0=LEN(ReferenceData!$L$7),"",ReferenceData!$L$7),"") -> 47.964704 | AB7: =IFERROR(IF(0=LEN(ReferenceData!$K$7),"",ReferenceData!$K$7),"") -> 48.953407 | AC7: =IFERROR(IF(0=LEN(ReferenceData!$J$7),"",ReferenceData!$J$7),"") -> 50.136733 | AD7: =IFERROR(IF(0=LEN(ReferenceData!$I$7),"",ReferenceData!$I$7),"") -> 51.126709 | AE7: =IFERROR(IF(0=LEN(ReferenceData!$H$7),"",ReferenceData!$H$7),"") -> 52.638601 | AF7: =IFERROR(IF(0=LEN(ReferenceData!$G$7),"",ReferenceData!$G$7),"") -> 53.441266 | AG7: =IFERROR(IF(0=LEN(ReferenceData!$F$7),"",ReferenceData!$F$7),"") -> 54.081124
A8: =IFERROR(IF(0=LEN(ReferenceData!$A$8),"",ReferenceData!$A$8),"") -> Passive % Of All Fixed Income Funds | B8: =IFERROR(IF(0=LEN(ReferenceData!$B$8),"",ReferenceData!$B$8),"") | C8: =IFERROR(IF(0=LEN(ReferenceData!$C$8),"",ReferenceData!$C$8),"") | D8: =IFERROR(IF(0=LEN(ReferenceData!$D$8),"",ReferenceData!$D$8),"") | E8: =IFERROR(IF(0=LEN(ReferenceData!$E$8),"",ReferenceData!$E$8),"") -> Expression | F8: =IFERROR(IF(0=LEN(ReferenceData!$AG$8),"",ReferenceData!$AG$8),"") -> 15.79825 | G8: =IFERROR(IF(0=LEN(ReferenceData!$AF$8),"",ReferenceData!$AF$8),"") -> 15.511313 | H8: =IFERROR(IF(0=LEN(ReferenceData!$AE$8),"",ReferenceData!$AE$8),"") -> 15.865767 | I8: =IFERROR(IF(0=LEN(ReferenceData!$AD$8),"",ReferenceData!$AD$8),"") -> 16.241755 | J8: =IFERROR(IF(0=LEN(ReferenceData!$AC$8),"",ReferenceData!$AC$8),"") -> 16.767667 | K8: =IFERROR(IF(0=LEN(ReferenceData!$AB$8),"",ReferenceData!$AB$8),"") -> 18.517265 | L8: =IFERROR(IF(0=LEN(ReferenceData!$AA$8),"",ReferenceData!$AA$8),"") -> 19.511031 | M8: =IFERROR(IF(0=LEN(ReferenceData!$Z$8),"",ReferenceData!$Z$8),"") -> 20.954989 | N8: =IFERROR(IF(0=LEN(ReferenceData!$Y$8),"",ReferenceData!$Y$8),"") -> 22.318445 | O8: =IFERROR(IF(0=LEN(ReferenceData!$X$8),"",ReferenceData!$X$8),"") -> 23.272017 | P8: =IFERROR(IF(0=LEN(ReferenceData!$W$8),"",ReferenceData!$W$8),"") -> 24.783601 | Q8: =IFERROR(IF(0=LEN(ReferenceData!$V$8),"",ReferenceData!$V$8),"") -> 26.11505 | R8: =IFERROR(IF(0=LEN(ReferenceData!$U$8),"",ReferenceData!$U$8),"") -> 26.764075 | S8: =IFERROR(IF(0=LEN(ReferenceData!$T$8),"",ReferenceData!$T$8),"") -> 28.077709 | T8: =IFERROR(IF(0=LEN(ReferenceData!$S$8),"",ReferenceData!$S$8),"") -> 29.469729 | U8: =IFERROR(IF(0=LEN(ReferenceData!$R$8),"",ReferenceData!$R$8),"") -> 29.576187 | V8: =IFERROR(IF(0=LEN(ReferenceData!$Q$8),"",ReferenceData!$Q$8),"") -> 31.117414 | W8: =IFERROR(IF(0=LEN(ReferenceData!$P$8),"",ReferenceData!$P$8),"") -> 31.159512 | X8: =IFERROR(IF(0=LEN(ReferenceData!$O$8),"",ReferenceData!$O$8),"") -> 31.377922 | Y8: =IFERROR(IF(0=LEN(ReferenceData!$N$8),"",ReferenceData!$N$8),"") -> 31.896073 | Z8: =IFERROR(IF(0=LEN(ReferenceData!$M$8),"",ReferenceData!$M$8),"") -> 34.004146 | AA8: =IFERROR(IF(0=LEN(ReferenceData!$L$8),"",ReferenceData!$L$8),"") -> 36.325285 | AB8: =IFERROR(IF(0=LEN(ReferenceData!$K$8),"",ReferenceData!$K$8),"") -> 36.457365 | AC8: =IFERROR(IF(0=LEN(ReferenceData!$J$8),"",ReferenceData!$J$8),"") -> 37.408446 | AD8: =IFERROR(IF(0=LEN(ReferenceData!$I$8),"",ReferenceData!$I$8),"") -> 37.440026 | AE8: =IFERROR(IF(0=LEN(ReferenceData!$H$8),"",ReferenceData!$H$8),"") -> 37.551428 | AF8: =IFERROR(IF(0=LEN(ReferenceData!$G$8),"",ReferenceData!$G$8),"") -> 38.189375 | AG8: =IFERROR(IF(0=LEN(ReferenceData!$F$8),"",ReferenceData!$F$8),"") -> 38.508901
A9: =IFERROR(IF(0=LEN(ReferenceData!$A$9),"",ReferenceData!$A$9),"") -> Passive % Of All Equity Funds | B9: =IFERROR(IF(0=LEN(ReferenceData!$B$9),"",ReferenceData!$B$9),"") | C9: =IFERROR(IF(0=LEN(ReferenceData!$C$9),"",ReferenceData!$C$9),"") | D9: =IFERROR(IF(0=LEN(ReferenceData!$D$9),"",ReferenceData!$D$9),"") | E9: =IFERROR(IF(0=LEN(ReferenceData!$E$9),"",ReferenceData!$E$9),"") -> Expression | F9: =IFERROR(IF(0=LEN(ReferenceData!$AG$9),"",ReferenceData!$AG$9),"") -> 32.260807 | G9: =IFERROR(IF(0=LEN(ReferenceData!$AF$9),"",ReferenceData!$AF$9),"") -> 33.024504 | H9: =IFERROR(IF(0=LEN(ReferenceData!$AE$9),"",ReferenceData!$AE$9),"") -> 33.706485 | I9: =IFERROR(IF(0=LEN(ReferenceData!$AD$9),"",ReferenceData!$AD$9),"") -> 34.371796 | J9: =IFERROR(IF(0=LEN(ReferenceData!$AC$9),"",ReferenceData!$AC$9),"") -> 34.973911 | K9: =IFERROR(IF(0=LEN(ReferenceData!$AB$9),"",ReferenceData!$AB$9),"") -> 36.808456 | L9: =IFERROR(IF(0=LEN(ReferenceData!$AA$9),"",ReferenceData!$AA$9),"") -> 37.733408 | M9: =IFERROR(IF(0=LEN(ReferenceData!$Z$9),"",ReferenceData!$Z$9),"") -> 39.017128 | N9: =IFERROR(IF(0=LEN(ReferenceData!$Y$9),"",ReferenceData!$Y$9),"") -> 40.179994 | O9: =IFERROR(IF(0=LEN(ReferenceData!$X$9),"",ReferenceData!$X$9),"") -> 42.348753 | P9: =IFERROR(IF(0=LEN(ReferenceData!$W$9),"",ReferenceData!$W$9),"") -> 43.8448 | Q9: =IFERROR(IF(0=LEN(ReferenceData!$V$9),"",ReferenceData!$V$9),"") -> 45.449154 | R9: =IFERROR(IF(0=LEN(ReferenceData!$U$9),"",ReferenceData!$U$9),"") -> 45.835681 | S9: =IFERROR(IF(0=LEN(ReferenceData!$T$9),"",ReferenceData!$T$9),"") -> 48.345162 | T9: =IFERROR(IF(0=LEN(ReferenceData!$S$9),"",ReferenceData!$S$9),"") -> 49.255014 | U9: =IFERROR(IF(0=LEN(ReferenceData!$R$9),"",ReferenceData!$R$9),"") -> 49.626281 | V9: =IFERROR(IF(0=LEN(ReferenceData!$Q$9),"",ReferenceData!$Q$9),"") -> 49.461105 | W9: =IFERROR(IF(0=LEN(ReferenceData!$P$9),"",ReferenceData!$P$9),"") -> 50.207717 | X9: =IFERROR(IF(0=LEN(ReferenceData!$O$9),"",ReferenceData!$O$9),"") -> 51.397546 | Y9: =IFERROR(IF(0=LEN(ReferenceData!$N$9),"",ReferenceData!$N$9),"") -> 53.073346 | Z9: =IFERROR(IF(0=LEN(ReferenceData!$M$9),"",ReferenceData!$M$9),"") -> 54.656961 | AA9: =IFERROR(IF(0=LEN(ReferenceData!$L$9),"",ReferenceData!$L$9),"") -> 55.749346 | AB9: =IFERROR(IF(0=LEN(ReferenceData!$K$9),"",ReferenceData!$K$9),"") -> 56.394548 | AC9: =IFERROR(IF(0=LEN(ReferenceData!$J$9),"",ReferenceData!$J$9),"") -> 57.433797 | AD9: =IFERROR(IF(0=LEN(ReferenceData!$I$9),"",ReferenceData!$I$9),"") -> 58.220891 | AE9: =IFERROR(IF(0=LEN(ReferenceData!$H$9),"",ReferenceData!$H$9),"") -> 59.983843 | AF9: =IFERROR(IF(0=LEN(ReferenceData!$G$9),"",ReferenceData!$G$9),"") -> 60.580739 | AG9: =IFERROR(IF(0=LEN(ReferenceData!$F$9),"",ReferenceData!$F$9),"") -> 61.171637
A10: =IFERROR(IF(0=LEN(ReferenceData!$A$10),"",ReferenceData!$A$10),"") -> Passive % Of Domestic Equity Funds | B10: =IFERROR(IF(0=LEN(ReferenceData!$B$10),"",ReferenceData!$B$10),"") | C10: =IFERROR(IF(0=LEN(ReferenceData!$C$10),"",ReferenceData!$C$10),"") | D10: =IFERROR(IF(0=LEN(ReferenceData!$D$10),"",ReferenceData!$D$10),"") | E10: =IFERROR(IF(0=LEN(ReferenceData!$E$10),"",ReferenceData!$E$10),"") -> Expression | F10: =IFERROR(IF(0=LEN(ReferenceData!$AG$10),"",ReferenceData!$AG$10),"") -> 34.647602 | G10: =IFERROR(IF(0=LEN(ReferenceData!$AF$10),"",ReferenceData!$AF$10),"") -> 35.14822 | H10: =IFERROR(IF(0=LEN(ReferenceData!$AE$10),"",ReferenceData!$AE$10),"") -> 36.608365 | I10: =IFERROR(IF(0=LEN(ReferenceData!$AD$10),"",ReferenceData!$AD$10),"") -> 37.340625 | J10: =IFERROR(IF(0=LEN(ReferenceData!$AC$10),"",ReferenceData!$AC$10),"") -> 38.070971 | K10: =IFERROR(IF(0=LEN(ReferenceData!$AB$10),"",ReferenceData!$AB$10),"") -> 40.150037 | L10: =IFERROR(IF(0=LEN(ReferenceData!$AA$10),"",ReferenceData!$AA$10),"") -> 40.552479 | M10: =IFERROR(IF(0=LEN(ReferenceData!$Z$10),"",ReferenceData!$Z$10),"") -> 41.796638 | N10: =IFERROR(IF(0=LEN(ReferenceData!$Y$10),"",ReferenceData!$Y$10),"") -> 43.197555 | O10: =IFERROR(IF(0=LEN(ReferenceData!$X$10),"",ReferenceData!$X$10),"") -> 45.434496 | P10: =IFERROR(IF(0=LEN(ReferenceData!$W$10),"",ReferenceData!$W$10),"") -> 46.64149 | Q10: =IFERROR(IF(0=LEN(ReferenceData!$V$10),"",ReferenceData!$V$10),"") -> 48.355863 | R10: =IFERROR(IF(0=LEN(ReferenceData!$U$10),"",ReferenceData!$U$10),"") -> 48.591687 | S10: =IFERROR(IF(0=LEN(ReferenceData!$T$10),"",ReferenceData!$T$10),"") -> 50.829992 | T10: =IFERROR(IF(0=LEN(ReferenceData!$S$10),"",ReferenceData!$S$10),"") -> 51.778042 | U10: =IFERROR(IF(0=LEN(ReferenceData!$R$10),"",ReferenceData!$R$10),"") -> 52.420491 | V10: =IFERROR(IF(0=LEN(ReferenceData!$Q$10),"",ReferenceData!$Q$10),"") -> 52.268226 | W10: =IFERROR(IF(0=LEN(ReferenceData!$P$10),"",ReferenceData!$P$10),"") -> 53.332524 | X10: =IFERROR(IF(0=LEN(ReferenceData!$O$10),"",ReferenceData!$O$10),"") -> 54.525873 | Y10: =IFERROR(IF(0=LEN(ReferenceData!$N$10),"",ReferenceData!$N$10),"") -> 56.209454 | Z10: =IFERROR(IF(0=LEN(ReferenceData!$M$10),"",ReferenceData!$M$10),"") -> 57.703752 | AA10: =IFERROR(IF(0=LEN(ReferenceData!$L$10),"",ReferenceData!$L$10),"") -> 58.697585 | AB10: =IFERROR(IF(0=LEN(ReferenceData!$K$10),"",ReferenceData!$K$10),"") -> 59.402437 | AC10: =IFERROR(IF(0=LEN(ReferenceData!$J$10),"",ReferenceData!$J$10),"") -> 60.379999 | AD10: =IFERROR(IF(0=LEN(ReferenceData!$I$10),"",ReferenceData!$I$10),"") -> 61.174772 | AE10: =IFERROR(IF(0=LEN(ReferenceData!$H$10),"",ReferenceData!$H$10),"") -> 62.958835 | AF10: =IFERROR(IF(0=LEN(ReferenceData!$G$10),"",ReferenceData!$G$10),"") -> 63.665222 | AG10: =IFERROR(IF(0=LEN(ReferenceData!$F$10),"",ReferenceData!$F$10),"") -> 64.135501
A11: =IFERROR(IF(0=LEN(ReferenceData!$A$11),"",ReferenceData!$A$11),"") -> Passive % Of Non-Domestic Equity Funds | B11: =IFERROR(IF(0=LEN(ReferenceData!$B$11),"",ReferenceData!$B$11),"") | C11: =IFERROR(IF(0=LEN(ReferenceData!$C$11),"",ReferenceData!$C$11),"") | D11: =IFERROR(IF(0=LEN(ReferenceData!$D$11),"",ReferenceData!$D$11),"") | E11: =IFERROR(IF(0=LEN(ReferenceData!$E$11),"",ReferenceData!$E$11),"") -> Expression | F11: =IFERROR(IF(0=LEN(ReferenceData!$AG$11),"",ReferenceData!$AG$11),"") -> 26.117961 | G11: =IFERROR(IF(0=LEN(ReferenceData!$AF$11),"",ReferenceData!$AF$11),"") -> 28.061589 | H11: =IFERROR(IF(0=LEN(ReferenceData!$AE$11),"",ReferenceData!$AE$11),"") -> 26.284888 | I11: =IFERROR(IF(0=LEN(ReferenceData!$AD$11),"",ReferenceData!$AD$11),"") -> 26.847737 | J11: =IFERROR(IF(0=LEN(ReferenceData!$AC$11),"",ReferenceData!$AC$11),"") -> 27.454987 | K11: =IFERROR(IF(0=LEN(ReferenceData!$AB$11),"",ReferenceData!$AB$11),"") -> 27.828769 | L11: =IFERROR(IF(0=LEN(ReferenceData!$AA$11),"",ReferenceData!$AA$11),"") -> 30.77396 | M11: =IFERROR(IF(0=LEN(ReferenceData!$Z$11),"",ReferenceData!$Z$11),"") -> 31.853251 | N11: =IFERROR(IF(0=LEN(ReferenceData!$Y$11),"",ReferenceData!$Y$11),"") -> 32.269581 | O11: =IFERROR(IF(0=LEN(ReferenceData!$X$11),"",ReferenceData!$X$11),"") -> 33.87218 | P11: =IFERROR(IF(0=LEN(ReferenceData!$W$11),"",ReferenceData!$W$11),"") -> 36.722086 | Q11: =IFERROR(IF(0=LEN(ReferenceData!$V$11),"",ReferenceData!$V$11),"") -> 38.363707 | R11: =IFERROR(IF(0=LEN(ReferenceData!$U$11),"",ReferenceData!$U$11),"") -> 38.740654 | S11: =IFERROR(IF(0=LEN(ReferenceData!$T$11),"",ReferenceData!$T$11),"") -> 41.815125 | T11: =IFERROR(IF(0=LEN(ReferenceData!$S$11),"",ReferenceData!$S$11),"") -> 42.27947 | U11: =IFERROR(IF(0=LEN(ReferenceData!$R$11),"",ReferenceData!$R$11),"") -> 41.931891 | V11: =IFERROR(IF(0=LEN(ReferenceData!$Q$11),"",ReferenceData!$Q$11),"") -> 41.335169 | W11: =IFERROR(IF(0=LEN(ReferenceData!$P$11),"",ReferenceData!$P$11),"") -> 41.174712 | X11: =IFERROR(IF(0=LEN(ReferenceData!$O$11),"",ReferenceData!$O$11),"") -> 41.899836 | Y11: =IFERROR(IF(0=LEN(ReferenceData!$N$11),"",ReferenceData!$N$11),"") -> 42.887222 | Z11: =IFERROR(IF(0=LEN(ReferenceData!$M$11),"",ReferenceData!$M$11),"") -> 44.753116 | AA11: =IFERROR(IF(0=LEN(ReferenceData!$L$11),"",ReferenceData!$L$11),"") -> 46.06725 | AB11: =IFERROR(IF(0=LEN(ReferenceData!$K$11),"",ReferenceData!$K$11),"") -> 46.205745 | AC11: =IFERROR(IF(0=LEN(ReferenceData!$J$11),"",ReferenceData!$J$11),"") -> 46.981378 | AD11: =IFERROR(IF(0=LEN(ReferenceData!$I$11),"",ReferenceData!$I$11),"") -> 47.213647 | AE11: =IFERROR(IF(0=LEN(ReferenceData!$H$11),"",ReferenceData!$H$11),"") -> 47.850299 | AF11: =IFERROR(IF(0=LEN(ReferenceData!$G$11),"",ReferenceData!$G$11),"") -> 49.180854 | AG11: =IFERROR(IF(0=LEN(ReferenceData!$F$11),"",ReferenceData!$F$11),"") -> 50.503502
A12: =IFERROR(IF(0=LEN(ReferenceData!$A$12),"",ReferenceData!$A$12),"") -> ETF & Mutual fund AUM ($MM) | B12: =IFERROR(IF(0=LEN(ReferenceData!$B$12),"",ReferenceData!$B$12),"") | C12: =IFERROR(IF(0=LEN(ReferenceData!$C$12),"",ReferenceData!$C$12),"") | D12: =IFERROR(IF(0=LEN(ReferenceData!$D$12),"",ReferenceData!$D$12),"") | E12: =IFERROR(IF(0=LEN(ReferenceData!$E$12),"",ReferenceData!$E$12),"") -> Heading | F12: =IFERROR(IF(0=LEN(ReferenceData!$AG$12),"",ReferenceData!$AG$12),"") | G12: =IFERROR(IF(0=LEN(ReferenceData!$AF$12),"",ReferenceData!$AF$12),"") | H12: =IFERROR(IF(0=LEN(ReferenceData!$AE$12),"",ReferenceData!$AE$12),"") | I12: =IFERROR(IF(0=LEN(ReferenceData!$AD$12),"",ReferenceData!$AD$12),"") | J12: =IFERROR(IF(0=LEN(ReferenceData!$AC$12),"",ReferenceData!$AC$12),"") | K12: =IFERROR(IF(0=LEN(ReferenceData!$AB$12),"",ReferenceData!$AB$12),"") | L12: =IFERROR(IF(0=LEN(ReferenceData!$AA$12),"",ReferenceData!$AA$12),"") | M12: =IFERROR(IF(0=LEN(ReferenceData!$Z$12),"",ReferenceData!$Z$12),"") | N12: =IFERROR(IF(0=LEN(ReferenceData!$Y$12),"",ReferenceData!$Y$12),"") | O12: =IFERROR(IF(0=LEN(ReferenceData!$X$12),"",ReferenceData!$X$12),"") | P12: =IFERROR(IF(0=LEN(ReferenceData!$W$12),"",ReferenceData!$W$12),"") | Q12: =IFERROR(IF(0=LEN(ReferenceData!$V$12),"",ReferenceData!$V$12),"") | R12: =IFERROR(IF(0=LEN(ReferenceData!$U$12),"",ReferenceData!$U$12),"") | S12: =IFERROR(IF(0=LEN(ReferenceData!$T$12),"",ReferenceData!$T$12),"") | T12: =IFERROR(IF(0=LEN(ReferenceData!$S$12),"",ReferenceData!$S$12),"") | U12: =IFERROR(IF(0=LEN(ReferenceData!$R$12),"",ReferenceData!$R$12),"") | V12: =IFERROR(IF(0=LEN(ReferenceData!$Q$12),"",ReferenceData!$Q$12),"") | W12: =IFERROR(IF(0=LEN(ReferenceData!$P$12),"",ReferenceData!$P$12),"") | X12: =IFERROR(IF(0=LEN(ReferenceData!$O$12),"",ReferenceData!$O$12),"") | Y12: =IFERROR(IF(0=LEN(ReferenceData!$N$12),"",ReferenceData!$N$12),"") | Z12: =IFERROR(IF(0=LEN(ReferenceData!$M$12),"",ReferenceData!$M$12),"") | AA12: =IFERROR(IF(0=LEN(ReferenceData!$L$12),"",ReferenceData!$L$12),"") | AB12: =IFERROR(IF(0=LEN(ReferenceData!$K$12),"",ReferenceData!$K$12),"") | AC12: =IFERROR(IF(0=LEN(ReferenceData!$J$12),"",ReferenceData!$J$12),"") | AD12: =IFERROR(IF(0=LEN(ReferenceData!$I$12),"",ReferenceData!$I$12),"") | AE12: =IFERROR(IF(0=LEN(ReferenceData!$H$12),"",ReferenceData!$H$12),"") | AF12: =IFERROR(IF(0=LEN(ReferenceData!$G$12),"",ReferenceData!$G$12),"") | AG12: =IFERROR(IF(0=LEN(ReferenceData!$F$12),"",ReferenceData!$F$12),"")
A13: =IFERROR(IF(0=LEN(ReferenceData!$A$13),"",ReferenceData!$A$13),"") -> All ETFs & Mutual Funds | B13: =IFERROR(IF(0=LEN(ReferenceData!$B$13),"",ReferenceData!$B$13),"") | C13: =IFERROR(IF(0=LEN(ReferenceData!$C$13),"",ReferenceData!$C$13),"") | D13: =IFERROR(IF(0=LEN(ReferenceData!$D$13),"",ReferenceData!$D$13),"") | E13: =IFERROR(IF(0=LEN(ReferenceData!$E$13),"",ReferenceData!$E$13),"") -> Sum | F13: =IFERROR(IF(0=LEN(ReferenceData!$AG$13),"",ReferenceData!$AG$13),"") -> 8871800 | G13: =IFERROR(IF(0=LEN(ReferenceData!$AF$13),"",ReferenceData!$AF$13),"") -> 9709500 | H13: =IFERROR(IF(0=LEN(ReferenceData!$AE$13),"",ReferenceData!$AE$13),"") -> 10582720 | I13: =IFERROR(IF(0=LEN(ReferenceData!$AD$13),"",ReferenceData!$AD$13),"") -> 11805870 | J13: =IFERROR(IF(0=LEN(ReferenceData!$AC$13),"",ReferenceData!$AC$13),"") -> 12902600 | K13: =IFERROR(IF(0=LEN(ReferenceData!$AB$13),"",ReferenceData!$AB$13),"") -> 13019770 | L13: =IFERROR(IF(0=LEN(ReferenceData!$AA$13),"",ReferenceData!$AA$13),"") -> 13543950 | M13: =IFERROR(IF(0=LEN(ReferenceData!$Z$13),"",ReferenceData!$Z$13),"") -> 13029040 | N13: =IFERROR(IF(0=LEN(ReferenceData!$Y$13),"",ReferenceData!$Y$13),"") -> 13640670 | O13: =IFERROR(IF(0=LEN(ReferenceData!$X$13),"",ReferenceData!$X$13),"") -> 14324120 | P13: =IFERROR(IF(0=LEN(ReferenceData!$W$13),"",ReferenceData!$W$13),"") -> 15915490 | Q13: =IFERROR(IF(0=LEN(ReferenceData!$V$13),"",ReferenceData!$V$13),"") -> 17409930 | R13: =IFERROR(IF(0=LEN(ReferenceData!$U$13),"",ReferenceData!$U$13),"") -> 17807800 | S13: =IFERROR(IF(0=LEN(ReferenceData!$T$13),"",ReferenceData!$T$13),"") -> 16331690 | T13: =IFERROR(IF(0=LEN(ReferenceData!$S$13),"",ReferenceData!$S$13),"") -> 18590680 | U13: =IFERROR(IF(0=LEN(ReferenceData!$R$13),"",ReferenceData!$R$13),"") -> 20340130 | V13: =IFERROR(IF(0=LEN(ReferenceData!$Q$13),"",ReferenceData!$Q$13),"") -> 19828130 | W13: =IFERROR(IF(0=LEN(ReferenceData!$P$13),"",ReferenceData!$P$13),"") -> 23408700 | X13: =IFERROR(IF(0=LEN(ReferenceData!$O$13),"",ReferenceData!$O$13),"") -> 26256600 | Y13: =IFERROR(IF(0=LEN(ReferenceData!$N$13),"",ReferenceData!$N$13),"") -> 27592600 | Z13: =IFERROR(IF(0=LEN(ReferenceData!$M$13),"",ReferenceData!$M$13),"") -> 22719500 | AA13: =IFERROR(IF(0=LEN(ReferenceData!$L$13),"",ReferenceData!$L$13),"") -> 22642900 | AB13: =IFERROR(IF(0=LEN(ReferenceData!$K$13),"",ReferenceData!$K$13),"") -> 24675300 | AC13: =IFERROR(IF(0=LEN(ReferenceData!$J$13),"",ReferenceData!$J$13),"") -> 26255600 | AD13: =IFERROR(IF(0=LEN(ReferenceData!$I$13),"",ReferenceData!$I$13),"") -> 28836200 | AE13: =IFERROR(IF(0=LEN(ReferenceData!$H$13),"",ReferenceData!$H$13),"") -> 30580600 | AF13: =IFERROR(IF(0=LEN(ReferenceData!$G$13),"",ReferenceData!$G$13),"") -> 32637700 | AG13: =IFERROR(IF(0=LEN(ReferenceData!$F$13),"",ReferenceData!$F$13),"") -> 35084700
A14: =IFERROR(IF(0=LEN(ReferenceData!$A$14),"",ReferenceData!$A$14),"") -> Passive Funds | B14: =IFERROR(IF(0=LEN(ReferenceData!$B$14),"",ReferenceData!$B$14),"") -> .BIATPTT G Index | C14: =IFERROR(IF(0=LEN(ReferenceData!$C$14),"",ReferenceData!$C$14),"") -> PR005 | D14: =IFERROR(IF(0=LEN(ReferenceData!$D$14),"",ReferenceData!$D$14),"") -> PX_LAST | E14: =IFERROR(IF(0=LEN(ReferenceData!$E$14),"",ReferenceData!$E$14),"") -> Dynamic | F14: =IFERROR(IF(0=LEN(ReferenceData!$AG$14),"",ReferenceData!$AG$14),"") -> 2219700 | G14: =IFERROR(IF(0=LEN(ReferenceData!$AF$14),"",ReferenceData!$AF$14),"") -> 2474180 | H14: =IFERROR(IF(0=LEN(ReferenceData!$AE$14),"",ReferenceData!$AE$14),"") -> 2761560 | I14: =IFERROR(IF(0=LEN(ReferenceData!$AD$14),"",ReferenceData!$AD$14),"") -> 3214070 | J14: =IFERROR(IF(0=LEN(ReferenceData!$AC$14),"",ReferenceData!$AC$14),"") -> 3575580 | K14: =IFERROR(IF(0=LEN(ReferenceData!$AB$14),"",ReferenceData!$AB$14),"") -> 3831310 | L14: =IFERROR(IF(0=LEN(ReferenceData!$AA$14),"",ReferenceData!$AA$14),"") -> 4119720 | M14: =IFERROR(IF(0=LEN(ReferenceData!$Z$14),"",ReferenceData!$Z$14),"") -> 4092380 | N14: =IFERROR(IF(0=LEN(ReferenceData!$Y$14),"",ReferenceData!$Y$14),"") -> 4433920 | O14: =IFERROR(IF(0=LEN(ReferenceData!$X$14),"",ReferenceData!$X$14),"") -> 4920680 | P14: =IFERROR(IF(0=LEN(ReferenceData!$W$14),"",ReferenceData!$W$14),"") -> 5733790 | Q14: =IFERROR(IF(0=LEN(ReferenceData!$V$14),"",ReferenceData!$V$14),"") -> 6572430 | R14: =IFERROR(IF(0=LEN(ReferenceData!$U$14),"",ReferenceData!$U$14),"") -> 6806800 | S14: =IFERROR(IF(0=LEN(ReferenceData!$T$14),"",ReferenceData!$T$14),"") -> 6506890 | T14: =IFERROR(IF(0=LEN(ReferenceData!$S$14),"",ReferenceData!$S$14),"") -> 7656780 | U14: =IFERROR(IF(0=LEN(ReferenceData!$R$14),"",ReferenceData!$R$14),"") -> 8462530 | V14: =IFERROR(IF(0=LEN(ReferenceData!$Q$14),"",ReferenceData!$Q$14),"") -> 8284230 | W14: =IFERROR(IF(0=LEN(ReferenceData!$P$14),"",ReferenceData!$P$14),"") -> 10017000 | X14: =IFERROR(IF(0=LEN(ReferenceData!$O$14),"",ReferenceData!$O$14),"") -> 11521000 | Y14: =IFERROR(IF(0=LEN(ReferenceData!$N$14),"",ReferenceData!$N$14),"") -> 12507300 | Z14: =IFERROR(IF(0=LEN(ReferenceData!$M$14),"",ReferenceData!$M$14),"") -> 10542800 | AA14: =IFERROR(IF(0=LEN(ReferenceData!$L$14),"",ReferenceData!$L$14),"") -> 10860600 | AB14: =IFERROR(IF(0=LEN(ReferenceData!$K$14),"",ReferenceData!$K$14),"") -> 12079400 | AC14: =IFERROR(IF(0=LEN(ReferenceData!$J$14),"",ReferenceData!$J$14),"") -> 13163700 | AD14: =IFERROR(IF(0=LEN(ReferenceData!$I$14),"",ReferenceData!$I$14),"") -> 14743000 | AE14: =IFERROR(IF(0=LEN(ReferenceData!$H$14),"",ReferenceData!$H$14),"") -> 16097200 | AF14: =IFERROR(IF(0=LEN(ReferenceData!$G$14),"",ReferenceData!$G$14),"") -> 17442000 | AG14: =IFERROR(IF(0=LEN(ReferenceData!$F$14),"",ReferenceData!$F$14),"") -> 18974200
A15: =IFERROR(IF(0=LEN(ReferenceData!$A$15),"",ReferenceData!$A$15),"") -> Passive Mutual Funds | B15: =IFERROR(IF(0=LEN(ReferenceData!$B$15),"",ReferenceData!$B$15),"") -> .BIAMPTT G Index | C15: =IFERROR(IF(0=LEN(ReferenceData!$C$15),"",ReferenceData!$C$15),"") -> PR005 | D15: =IFERROR(IF(0=LEN(ReferenceData!$D$15),"",ReferenceData!$D$15),"") -> PX_LAST | E15: =IFERROR(IF(0=LEN(ReferenceData!$E$15),"",ReferenceData!$E$15),"") -> Dynamic | F15: =IFERROR(IF(0=LEN(ReferenceData!$AG$15),"",ReferenceData!$AG$15),"") -> 1073950 | G15: =IFERROR(IF(0=LEN(ReferenceData!$AF$15),"",ReferenceData!$AF$15),"") -> 1178570 | H15: =IFERROR(IF(0=LEN(ReferenceData!$AE$15),"",ReferenceData!$AE$15),"") -> 1349510 | I15: =IFERROR(IF(0=LEN(ReferenceData!$AD$15),"",ReferenceData!$AD$15),"") -> 1575100 | J15: =IFERROR(IF(0=LEN(ReferenceData!$AC$15),"",ReferenceData!$AC$15),"") -> 1772810 | K15: =IFERROR(IF(0=LEN(ReferenceData!$AB$15),"",ReferenceData!$AB$15),"") -> 1902020 | L15: =IFERROR(IF(0=LEN(ReferenceData!$AA$15),"",ReferenceData!$AA$15),"") -> 2042090 | M15: =IFERROR(IF(0=LEN(ReferenceData!$Z$15),"",ReferenceData!$Z$15),"") -> 2054650 | N15: =IFERROR(IF(0=LEN(ReferenceData!$Y$15),"",ReferenceData!$Y$15),"") -> 2227660 | O15: =IFERROR(IF(0=LEN(ReferenceData!$X$15),"",ReferenceData!$X$15),"") -> 2415390 | P15: =IFERROR(IF(0=LEN(ReferenceData!$W$15),"",ReferenceData!$W$15),"") -> 2822350 | Q15: =IFERROR(IF(0=LEN(ReferenceData!$V$15),"",ReferenceData!$V$15),"") -> 3184940 | R15: =IFERROR(IF(0=LEN(ReferenceData!$U$15),"",ReferenceData!$U$15),"") -> 3331210 | S15: =IFERROR(IF(0=LEN(ReferenceData!$T$15),"",ReferenceData!$T$15),"") -> 3182710 | T15: =IFERROR(IF(0=LEN(ReferenceData!$S$15),"",ReferenceData!$S$15),"") -> 3786900 | U15: =IFERROR(IF(0=LEN(ReferenceData!$R$15),"",ReferenceData!$R$15),"") -> 4144870 | V15: =IFERROR(IF(0=LEN(ReferenceData!$Q$15),"",ReferenceData!$Q$15),"") -> 3999840 | W15: =IFERROR(IF(0=LEN(ReferenceData!$P$15),"",ReferenceData!$P$15),"") -> 4687590 | X15: =IFERROR(IF(0=LEN(ReferenceData!$O$15),"",ReferenceData!$O$15),"") -> 5257020 | Y15: =IFERROR(IF(0=LEN(ReferenceData!$N$15),"",ReferenceData!$N$15),"") -> 5630760 | Z15: =IFERROR(IF(0=LEN(ReferenceData!$M$15),"",ReferenceData!$M$15),"") -> 4634540 | AA15: =IFERROR(IF(0=LEN(ReferenceData!$L$15),"",ReferenceData!$L$15),"") -> 4692710 | AB15: =IFERROR(IF(0=LEN(ReferenceData!$K$15),"",ReferenceData!$K$15),"") -> 5213990 | AC15: =IFERROR(IF(0=LEN(ReferenceData!$J$15),"",ReferenceData!$J$15),"") -> 5605390 | AD15: =IFERROR(IF(0=LEN(ReferenceData!$I$15),"",ReferenceData!$I$15),"") -> 6213380 | AE15: =IFERROR(IF(0=LEN(ReferenceData!$H$15),"",ReferenceData!$H$15),"") -> 6612880 | AF15: =IFERROR(IF(0=LEN(ReferenceData!$G$15),"",ReferenceData!$G$15),"") -> 7058640 | AG15: =IFERROR(IF(0=LEN(ReferenceData!$F$15),"",ReferenceData!$F$15),"") -> 7353540
A16: =IFERROR(IF(0=LEN(ReferenceData!$A$16),"",ReferenceData!$A$16),"") -> Passive ETFs | B16: =IFERROR(IF(0=LEN(ReferenceData!$B$16),"",ReferenceData!$B$16),"") | C16: =IFERROR(IF(0=LEN(ReferenceData!$C$16),"",ReferenceData!$C$16),"") | D16: =IFERROR(IF(0=LEN(ReferenceData!$D$16),"",ReferenceData!$D$16),"") | E16: =IFERROR(IF(0=LEN(ReferenceData!$E$16),"",ReferenceData!$E$16),"") -> Expression | F16: =IFERROR(IF(0=LEN(ReferenceData!$AG$16),"",ReferenceData!$AG$16),"") -> 1145750 | G16: =IFERROR(IF(0=LEN(ReferenceData!$AF$16),"",ReferenceData!$AF$16),"") -> 1295610 | H16: =IFERROR(IF(0=LEN(ReferenceData!$AE$16),"",ReferenceData!$AE$16),"") -> 1412050 | I16: =IFERROR(IF(0=LEN(ReferenceData!$AD$16),"",ReferenceData!$AD$16),"") -> 1638970 | J16: =IFERROR(IF(0=LEN(ReferenceData!$AC$16),"",ReferenceData!$AC$16),"") -> 1802770 | K16: =IFERROR(IF(0=LEN(ReferenceData!$AB$16),"",ReferenceData!$AB$16),"") -> 1929290 | L16: =IFERROR(IF(0=LEN(ReferenceData!$AA$16),"",ReferenceData!$AA$16),"") -> 2077630 | M16: =IFERROR(IF(0=LEN(ReferenceData!$Z$16),"",ReferenceData!$Z$16),"") -> 2037730 | N16: =IFERROR(IF(0=LEN(ReferenceData!$Y$16),"",ReferenceData!$Y$16),"") -> 2206260 | O16: =IFERROR(IF(0=LEN(ReferenceData!$X$16),"",ReferenceData!$X$16),"") -> 2505290 | P16: =IFERROR(IF(0=LEN(ReferenceData!$W$16),"",ReferenceData!$W$16),"") -> 2911440 | Q16: =IFERROR(IF(0=LEN(ReferenceData!$V$16),"",ReferenceData!$V$16),"") -> 3387490 | R16: =IFERROR(IF(0=LEN(ReferenceData!$U$16),"",ReferenceData!$U$16),"") -> 3475590 | S16: =IFERROR(IF(0=LEN(ReferenceData!$T$16),"",ReferenceData!$T$16),"") -> 3324180 | T16: =IFERROR(IF(0=LEN(ReferenceData!$S$16),"",ReferenceData!$S$16),"") -> 3869880 | U16: =IFERROR(IF(0=LEN(ReferenceData!$R$16),"",ReferenceData!$R$16),"") -> 4317660 | V16: =IFERROR(IF(0=LEN(ReferenceData!$Q$16),"",ReferenceData!$Q$16),"") -> 4284390 | W16: =IFERROR(IF(0=LEN(ReferenceData!$P$16),"",ReferenceData!$P$16),"") -> 5329410 | X16: =IFERROR(IF(0=LEN(ReferenceData!$O$16),"",ReferenceData!$O$16),"") -> 6263980 | Y16: =IFERROR(IF(0=LEN(ReferenceData!$N$16),"",ReferenceData!$N$16),"") -> 6876540 | Z16: =IFERROR(IF(0=LEN(ReferenceData!$M$16),"",ReferenceData!$M$16),"") -> 5908260 | AA16: =IFERROR(IF(0=LEN(ReferenceData!$L$16),"",ReferenceData!$L$16),"") -> 6167890 | AB16: =IFERROR(IF(0=LEN(ReferenceData!$K$16),"",ReferenceData!$K$16),"") -> 6865410 | AC16: =IFERROR(IF(0=LEN(ReferenceData!$J$16),"",ReferenceData!$J$16),"") -> 7558310 | AD16: =IFERROR(IF(0=LEN(ReferenceData!$I$16),"",ReferenceData!$I$16),"") -> 8529620 | AE16: =IFERROR(IF(0=LEN(ReferenceData!$H$16),"",ReferenceData!$H$16),"") -> 9484320 | AF16: =IFERROR(IF(0=LEN(ReferenceData!$G$16),"",ReferenceData!$G$16),"") -> 10383360 | AG16: =IFERROR(IF(0=LEN(ReferenceData!$F$16),"",ReferenceData!$F$16),"") -> 11620660
A17: =IFERROR(IF(0=LEN(ReferenceData!$A$17),"",ReferenceData!$A$17),"") -> Active Funds | B17: =IFERROR(IF(0=LEN(ReferenceData!$B$17),"",ReferenceData!$B$17),"") -> .BIATATT G Index | C17: =IFERROR(IF(0=LEN(ReferenceData!$C$17),"",ReferenceData!$C$17),"") -> PR005 | D17: =IFERROR(IF(0=LEN(ReferenceData!$D$17),"",ReferenceData!$D$17),"") -> PX_LAST | E17: =IFERROR(IF(0=LEN(ReferenceData!$E$17),"",ReferenceData!$E$17),"") -> Dynamic | F17: =IFERROR(IF(0=LEN(ReferenceData!$AG$17),"",ReferenceData!$AG$17),"") -> 6652100 | G17: =IFERROR(IF(0=LEN(ReferenceData!$AF$17),"",ReferenceData!$AF$17),"") -> 7235320 | H17: =IFERROR(IF(0=LEN(ReferenceData!$AE$17),"",ReferenceData!$AE$17),"") -> 7821160 | I17: =IFERROR(IF(0=LEN(ReferenceData!$AD$17),"",ReferenceData!$AD$17),"") -> 8591800 | J17: =IFERROR(IF(0=LEN(ReferenceData!$AC$17),"",ReferenceData!$AC$17),"") -> 9327020 | K17: =IFERROR(IF(0=LEN(ReferenceData!$AB$17),"",ReferenceData!$AB$17),"") -> 9188460 | L17: =IFERROR(IF(0=LEN(ReferenceData!$AA$17),"",ReferenceData!$AA$17),"") -> 9424230 | M17: =IFERROR(IF(0=LEN(ReferenceData!$Z$17),"",ReferenceData!$Z$17),"") -> 8936660 | N17: =IFERROR(IF(0=LEN(ReferenceData!$Y$17),"",ReferenceData!$Y$17),"") -> 9206750 | O17: =IFERROR(IF(0=LEN(ReferenceData!$X$17),"",ReferenceData!$X$17),"") -> 9403440 | P17: =IFERROR(IF(0=LEN(ReferenceData!$W$17),"",ReferenceData!$W$17),"") -> 10181700 | Q17: =IFERROR(IF(0=LEN(ReferenceData!$V$17),"",ReferenceData!$V$17),"") -> 10837500 | R17: =IFERROR(IF(0=LEN(ReferenceData!$U$17),"",ReferenceData!$U$17),"") -> 11001000 | S17: =IFERROR(IF(0=LEN(ReferenceData!$T$17),"",ReferenceData!$T$17),"") -> 9824800 | T17: =IFERROR(IF(0=LEN(ReferenceData!$S$17),"",ReferenceData!$S$17),"") -> 10933900 | U17: =IFERROR(IF(0=LEN(ReferenceData!$R$17),"",ReferenceData!$R$17),"") -> 11877600 | V17: =IFERROR(IF(0=LEN(ReferenceData!$Q$17),"",ReferenceData!$Q$17),"") -> 11543900 | W17: =IFERROR(IF(0=LEN(ReferenceData!$P$17),"",ReferenceData!$P$17),"") -> 13391700 | X17: =IFERROR(IF(0=LEN(ReferenceData!$O$17),"",ReferenceData!$O$17),"") -> 14735600 | Y17: =IFERROR(IF(0=LEN(ReferenceData!$N$17),"",ReferenceData!$N$17),"") -> 15085300 | Z17: =IFERROR(IF(0=LEN(ReferenceData!$M$17),"",ReferenceData!$M$17),"") -> 12176700 | AA17: =IFERROR(IF(0=LEN(ReferenceData!$L$17),"",ReferenceData!$L$17),"") -> 11782300 | AB17: =IFERROR(IF(0=LEN(ReferenceData!$K$17),"",ReferenceData!$K$17),"") -> 12595900 | AC17: =IFERROR(IF(0=LEN(ReferenceData!$J$17),"",ReferenceData!$J$17),"") -> 13091900 | AD17: =IFERROR(IF(0=LEN(ReferenceData!$I$17),"",ReferenceData!$I$17),"") -> 14093200 | AE17: =IFERROR(IF(0=LEN(ReferenceData!$H$17),"",ReferenceData!$H$17),"") -> 14483400 | AF17: =IFERROR(IF(0=LEN(ReferenceData!$G$17),"",ReferenceData!$G$17),"") -> 15195700 | AG17: =IFERROR(IF(0=LEN(ReferenceData!$F$17),"",ReferenceData!$F$17),"") -> 16110500
A18: =IFERROR(IF(0=LEN(ReferenceData!$A$18),"",ReferenceData!$A$18),"") -> Active Mutual Funds | B18: =IFERROR(IF(0=LEN(ReferenceData!$B$18),"",ReferenceData!$B$18),"") -> .BIAMATT G Index | C18: =IFERROR(IF(0=LEN(ReferenceData!$C$18),"",ReferenceData!$C$18),"") -> PR005 | D18: =IFERROR(IF(0=LEN(ReferenceData!$D$18),"",ReferenceData!$D$18),"") -> PX_LAST | E18: =IFERROR(IF(0=LEN(ReferenceData!$E$18),"",ReferenceData!$E$18),"") -> Dynamic | F18: =IFERROR(IF(0=LEN(ReferenceData!$AG$18),"",ReferenceData!$AG$18),"") -> 6625190 | G18: =IFERROR(IF(0=LEN(ReferenceData!$AF$18),"",ReferenceData!$AF$18),"") -> 7209500 | H18: =IFERROR(IF(0=LEN(ReferenceData!$AE$18),"",ReferenceData!$AE$18),"") -> 7781640 | I18: =IFERROR(IF(0=LEN(ReferenceData!$AD$18),"",ReferenceData!$AD$18),"") -> 8547190 | J18: =IFERROR(IF(0=LEN(ReferenceData!$AC$18),"",ReferenceData!$AC$18),"") -> 9275590 | K18: =IFERROR(IF(0=LEN(ReferenceData!$AB$18),"",ReferenceData!$AB$18),"") -> 9135500 | L18: =IFERROR(IF(0=LEN(ReferenceData!$AA$18),"",ReferenceData!$AA$18),"") -> 9363890 | M18: =IFERROR(IF(0=LEN(ReferenceData!$Z$18),"",ReferenceData!$Z$18),"") -> 8876340 | N18: =IFERROR(IF(0=LEN(ReferenceData!$Y$18),"",ReferenceData!$Y$18),"") -> 9138660 | O18: =IFERROR(IF(0=LEN(ReferenceData!$X$18),"",ReferenceData!$X$18),"") -> 9323080 | P18: =IFERROR(IF(0=LEN(ReferenceData!$W$18),"",ReferenceData!$W$18),"") -> 10089600 | Q18: =IFERROR(IF(0=LEN(ReferenceData!$V$18),"",ReferenceData!$V$18),"") -> 10726200 | R18: =IFERROR(IF(0=LEN(ReferenceData!$U$18),"",ReferenceData!$U$18),"") -> 10872700 | S18: =IFERROR(IF(0=LEN(ReferenceData!$T$18),"",ReferenceData!$T$18),"") -> 9694990 | T18: =IFERROR(IF(0=LEN(ReferenceData!$S$18),"",ReferenceData!$S$18),"") -> 10781600 | U18: =IFERROR(IF(0=LEN(ReferenceData!$R$18),"",ReferenceData!$R$18),"") -> 11701500 | V18: =IFERROR(IF(0=LEN(ReferenceData!$Q$18),"",ReferenceData!$Q$18),"") -> 11361300 | W18: =IFERROR(IF(0=LEN(ReferenceData!$P$18),"",ReferenceData!$P$18),"") -> 13136100 | X18: =IFERROR(IF(0=LEN(ReferenceData!$O$18),"",ReferenceData!$O$18),"") -> 14403900 | Y18: =IFERROR(IF(0=LEN(ReferenceData!$N$18),"",ReferenceData!$N$18),"") -> 14726600 | Z18: =IFERROR(IF(0=LEN(ReferenceData!$M$18),"",ReferenceData!$M$18),"") -> 11808600 | AA18: =IFERROR(IF(0=LEN(ReferenceData!$L$18),"",ReferenceData!$L$18),"") -> 11368200 | AB18: =IFERROR(IF(0=LEN(ReferenceData!$K$18),"",ReferenceData!$K$18),"") -> 12101400 | AC18: =IFERROR(IF(0=LEN(ReferenceData!$J$18),"",ReferenceData!$J$18),"") -> 12502600 | AD18: =IFERROR(IF(0=LEN(ReferenceData!$I$18),"",ReferenceData!$I$18),"") -> 13335100 | AE18: =IFERROR(IF(0=LEN(ReferenceData!$H$18),"",ReferenceData!$H$18),"") -> 13538000 | AF18: =IFERROR(IF(0=LEN(ReferenceData!$G$18),"",ReferenceData!$G$18),"") -> 14039000 | AG18: =IFERROR(IF(0=LEN(ReferenceData!$F$18),"",ReferenceData!$F$18),"") -> 14722300
A19: =IFERROR(IF(0=LEN(ReferenceData!$A$19),"",ReferenceData!$A$19),"") -> Active ETFs | B19: =IFERROR(IF(0=LEN(ReferenceData!$B$19),"",ReferenceData!$B$19),"") | C19: =IFERROR(IF(0=LEN(ReferenceData!$C$19),"",ReferenceData!$C$19),"") | D19: =IFERROR(IF(0=LEN(ReferenceData!$D$19),"",ReferenceData!$D$19),"") | E19: =IFERROR(IF(0=LEN(ReferenceData!$E$19),"",ReferenceData!$E$19),"") -> Expression | F19: =IFERROR(IF(0=LEN(ReferenceData!$AG$19),"",ReferenceData!$AG$19),"") -> 26910 | G19: =IFERROR(IF(0=LEN(ReferenceData!$AF$19),"",ReferenceData!$AF$19),"") -> 25820 | H19: =IFERROR(IF(0=LEN(ReferenceData!$AE$19),"",ReferenceData!$AE$19),"") -> 39520 | I19: =IFERROR(IF(0=LEN(ReferenceData!$AD$19),"",ReferenceData!$AD$19),"") -> 44610 | J19: =IFERROR(IF(0=LEN(ReferenceData!$AC$19),"",ReferenceData!$AC$19),"") -> 51430 | K19: =IFERROR(IF(0=LEN(ReferenceData!$AB$19),"",ReferenceData!$AB$19),"") -> 52960 | L19: =IFERROR(IF(0=LEN(ReferenceData!$AA$19),"",ReferenceData!$AA$19),"") -> 60340 | M19: =IFERROR(IF(0=LEN(ReferenceData!$Z$19),"",ReferenceData!$Z$19),"") -> 60320 | N19: =IFERROR(IF(0=LEN(ReferenceData!$Y$19),"",ReferenceData!$Y$19),"") -> 68090 | O19: =IFERROR(IF(0=LEN(ReferenceData!$X$19),"",ReferenceData!$X$19),"") -> 80360 | P19: =IFERROR(IF(0=LEN(ReferenceData!$W$19),"",ReferenceData!$W$19),"") -> 92100 | Q19: =IFERROR(IF(0=LEN(ReferenceData!$V$19),"",ReferenceData!$V$19),"") -> 111300 | R19: =IFERROR(IF(0=LEN(ReferenceData!$U$19),"",ReferenceData!$U$19),"") -> 128300 | S19: =IFERROR(IF(0=LEN(ReferenceData!$T$19),"",ReferenceData!$T$19),"") -> 129810 | T19: =IFERROR(IF(0=LEN(ReferenceData!$S$19),"",ReferenceData!$S$19),"") -> 152300 | U19: =IFERROR(IF(0=LEN(ReferenceData!$R$19),"",ReferenceData!$R$19),"") -> 176100 | V19: =IFERROR(IF(0=LEN(ReferenceData!$Q$19),"",ReferenceData!$Q$19),"") -> 182600 | W19: =IFERROR(IF(0=LEN(ReferenceData!$P$19),"",ReferenceData!$P$19),"") -> 255600 | X19: =IFERROR(IF(0=LEN(ReferenceData!$O$19),"",ReferenceData!$O$19),"") -> 331700 | Y19: =IFERROR(IF(0=LEN(ReferenceData!$N$19),"",ReferenceData!$N$19),"") -> 358700 | Z19: =IFERROR(IF(0=LEN(ReferenceData!$M$19),"",ReferenceData!$M$19),"") -> 368100 | AA19: =IFERROR(IF(0=LEN(ReferenceData!$L$19),"",ReferenceData!$L$19),"") -> 414100 | AB19: =IFERROR(IF(0=LEN(ReferenceData!$K$19),"",ReferenceData!$K$19),"") -> 494500 | AC19: =IFERROR(IF(0=LEN(ReferenceData!$J$19),"",ReferenceData!$J$19),"") -> 589300 | AD19: =IFERROR(IF(0=LEN(ReferenceData!$I$19),"",ReferenceData!$I$19),"") -> 758100 | AE19: =IFERROR(IF(0=LEN(ReferenceData!$H$19),"",ReferenceData!$H$19),"") -> 945400 | AF19: =IFERROR(IF(0=LEN(ReferenceData!$G$19),"",ReferenceData!$G$19),"") -> 1156700 | AG19: =IFERROR(IF(0=LEN(ReferenceData!$F$19),"",ReferenceData!$F$19),"") -> 1388200
A20: =IFERROR(IF(0=LEN(ReferenceData!$A$20),"",ReferenceData!$A$20),"") -> All Fixed Income Funds | B20: =IFERROR(IF(0=LEN(ReferenceData!$B$20),"",ReferenceData!$B$20),"") | C20: =IFERROR(IF(0=LEN(ReferenceData!$C$20),"",ReferenceData!$C$20),"") | D20: =IFERROR(IF(0=LEN(ReferenceData!$D$20),"",ReferenceData!$D$20),"") | E20: =IFERROR(IF(0=LEN(ReferenceData!$E$20),"",ReferenceData!$E$20),"") -> Sum | F20: =IFERROR(IF(0=LEN(ReferenceData!$AG$20),"",ReferenceData!$AG$20),"") -> 2826984 | G20: =IFERROR(IF(0=LEN(ReferenceData!$AF$20),"",ReferenceData!$AF$20),"") -> 3097681 | H20: =IFERROR(IF(0=LEN(ReferenceData!$AE$20),"",ReferenceData!$AE$20),"") -> 3111397 | I20: =IFERROR(IF(0=LEN(ReferenceData!$AD$20),"",ReferenceData!$AD$20),"") -> 3059854 | J20: =IFERROR(IF(0=LEN(ReferenceData!$AC$20),"",ReferenceData!$AC$20),"") -> 3285478 | K20: =IFERROR(IF(0=LEN(ReferenceData!$AB$20),"",ReferenceData!$AB$20),"") -> 3308345 | L20: =IFERROR(IF(0=LEN(ReferenceData!$AA$20),"",ReferenceData!$AA$20),"") -> 3370027 | M20: =IFERROR(IF(0=LEN(ReferenceData!$Z$20),"",ReferenceData!$Z$20),"") -> 3335201 | N20: =IFERROR(IF(0=LEN(ReferenceData!$Y$20),"",ReferenceData!$Y$20),"") -> 3619598 | O20: =IFERROR(IF(0=LEN(ReferenceData!$X$20),"",ReferenceData!$X$20),"") -> 3668062 | P20: =IFERROR(IF(0=LEN(ReferenceData!$W$20),"",ReferenceData!$W$20),"") -> 3988585 | Q20: =IFERROR(IF(0=LEN(ReferenceData!$V$20),"",ReferenceData!$V$20),"") -> 4203400 | R20: =IFERROR(IF(0=LEN(ReferenceData!$U$20),"",ReferenceData!$U$20),"") -> 4324080 | S20: =IFERROR(IF(0=LEN(ReferenceData!$T$20),"",ReferenceData!$T$20),"") -> 4315060 | T20: =IFERROR(IF(0=LEN(ReferenceData!$S$20),"",ReferenceData!$S$20),"") -> 4737200 | U20: =IFERROR(IF(0=LEN(ReferenceData!$R$20),"",ReferenceData!$R$20),"") -> 5192150 | V20: =IFERROR(IF(0=LEN(ReferenceData!$Q$20),"",ReferenceData!$Q$20),"") -> 5394600 | W20: =IFERROR(IF(0=LEN(ReferenceData!$P$20),"",ReferenceData!$P$20),"") -> 5999420 | X20: =IFERROR(IF(0=LEN(ReferenceData!$O$20),"",ReferenceData!$O$20),"") -> 6422860 | Y20: =IFERROR(IF(0=LEN(ReferenceData!$N$20),"",ReferenceData!$N$20),"") -> 6645050 | Z20: =IFERROR(IF(0=LEN(ReferenceData!$M$20),"",ReferenceData!$M$20),"") -> 5818320 | AA20: =IFERROR(IF(0=LEN(ReferenceData!$L$20),"",ReferenceData!$L$20),"") -> 5610830 | AB20: =IFERROR(IF(0=LEN(ReferenceData!$K$20),"",ReferenceData!$K$20),"") -> 5753570 | AC20: =IFERROR(IF(0=LEN(ReferenceData!$J$20),"",ReferenceData!$J$20),"") -> 6003270 | AD20: =IFERROR(IF(0=LEN(ReferenceData!$I$20),"",ReferenceData!$I$20),"") -> 6231860 | AE20: =IFERROR(IF(0=LEN(ReferenceData!$H$20),"",ReferenceData!$H$20),"") -> 6572320 | AF20: =IFERROR(IF(0=LEN(ReferenceData!$G$20),"",ReferenceData!$G$20),"") -> 6885580 | AG20: =IFERROR(IF(0=LEN(ReferenceData!$F$20),"",ReferenceData!$F$20),"") -> 7344380
A21: =IFERROR(IF(0=LEN(ReferenceData!$A$21),"",ReferenceData!$A$21),"") -> Passive Fixed Income | B21: =IFERROR(IF(0=LEN(ReferenceData!$B$21),"",ReferenceData!$B$21),"") -> .BIATPTF G Index | C21: =IFERROR(IF(0=LEN(ReferenceData!$C$21),"",ReferenceData!$C$21),"") -> PR005 | D21: =IFERROR(IF(0=LEN(ReferenceData!$D$21),"",ReferenceData!$D$21),"") -> PX_LAST | E21: =IFERROR(IF(0=LEN(ReferenceData!$E$21),"",ReferenceData!$E$21),"") -> Dynamic | F21: =IFERROR(IF(0=LEN(ReferenceData!$AG$21),"",ReferenceData!$AG$21),"") -> 446614 | G21: =IFERROR(IF(0=LEN(ReferenceData!$AF$21),"",ReferenceData!$AF$21),"") -> 480491 | H21: =IFERROR(IF(0=LEN(ReferenceData!$AE$21),"",ReferenceData!$AE$21),"") -> 493647 | I21: =IFERROR(IF(0=LEN(ReferenceData!$AD$21),"",ReferenceData!$AD$21),"") -> 496974 | J21: =IFERROR(IF(0=LEN(ReferenceData!$AC$21),"",ReferenceData!$AC$21),"") -> 550898 | K21: =IFERROR(IF(0=LEN(ReferenceData!$AB$21),"",ReferenceData!$AB$21),"") -> 612615 | L21: =IFERROR(IF(0=LEN(ReferenceData!$AA$21),"",ReferenceData!$AA$21),"") -> 657527 | M21: =IFERROR(IF(0=LEN(ReferenceData!$Z$21),"",ReferenceData!$Z$21),"") -> 698891 | N21: =IFERROR(IF(0=LEN(ReferenceData!$Y$21),"",ReferenceData!$Y$21),"") -> 807838 | O21: =IFERROR(IF(0=LEN(ReferenceData!$X$21),"",ReferenceData!$X$21),"") -> 853632 | P21: =IFERROR(IF(0=LEN(ReferenceData!$W$21),"",ReferenceData!$W$21),"") -> 988515 | Q21: =IFERROR(IF(0=LEN(ReferenceData!$V$21),"",ReferenceData!$V$21),"") -> 1097720 | R21: =IFERROR(IF(0=LEN(ReferenceData!$U$21),"",ReferenceData!$U$21),"") -> 1157300 | S21: =IFERROR(IF(0=LEN(ReferenceData!$T$21),"",ReferenceData!$T$21),"") -> 1211570 | T21: =IFERROR(IF(0=LEN(ReferenceData!$S$21),"",ReferenceData!$S$21),"") -> 1396040 | U21: =IFERROR(IF(0=LEN(ReferenceData!$R$21),"",ReferenceData!$R$21),"") -> 1535640 | V21: =IFERROR(IF(0=LEN(ReferenceData!$Q$21),"",ReferenceData!$Q$21),"") -> 1678660 | W21: =IFERROR(IF(0=LEN(ReferenceData!$P$21),"",ReferenceData!$P$21),"") -> 1869390 | X21: =IFERROR(IF(0=LEN(ReferenceData!$O$21),"",ReferenceData!$O$21),"") -> 2015360 | Y21: =IFERROR(IF(0=LEN(ReferenceData!$N$21),"",ReferenceData!$N$21),"") -> 2119510 | Z21: =IFERROR(IF(0=LEN(ReferenceData!$M$21),"",ReferenceData!$M$21),"") -> 1978470 | AA21: =IFERROR(IF(0=LEN(ReferenceData!$L$21),"",ReferenceData!$L$21),"") -> 2038150 | AB21: =IFERROR(IF(0=LEN(ReferenceData!$K$21),"",ReferenceData!$K$21),"") -> 2097600 | AC21: =IFERROR(IF(0=LEN(ReferenceData!$J$21),"",ReferenceData!$J$21),"") -> 2245730 | AD21: =IFERROR(IF(0=LEN(ReferenceData!$I$21),"",ReferenceData!$I$21),"") -> 2333210 | AE21: =IFERROR(IF(0=LEN(ReferenceData!$H$21),"",ReferenceData!$H$21),"") -> 2468000 | AF21: =IFERROR(IF(0=LEN(ReferenceData!$G$21),"",ReferenceData!$G$21),"") -> 2629560 | AG21: =IFERROR(IF(0=LEN(ReferenceData!$F$21),"",ReferenceData!$F$21),"") -> 2828240
A22: =IFERROR(IF(0=LEN(ReferenceData!$A$22),"",ReferenceData!$A$22),"") -> Passive Fixed Income Mutual Funds | B22: =IFERROR(IF(0=LEN(ReferenceData!$B$22),"",ReferenceData!$B$22),"") -> .BIAMPTF G Index | C22: =IFERROR(IF(0=LEN(ReferenceData!$C$22),"",ReferenceData!$C$22),"") -> PR005 | D22: =IFERROR(IF(0=LEN(ReferenceData!$D$22),"",ReferenceData!$D$22),"") -> PX_LAST | E22: =IFERROR(IF(0=LEN(ReferenceData!$E$22),"",ReferenceData!$E$22),"") -> Dynamic | F22: =IFERROR(IF(0=LEN(ReferenceData!$AG$22),"",ReferenceData!$AG$22),"") -> 220871 | G22: =IFERROR(IF(0=LEN(ReferenceData!$AF$22),"",ReferenceData!$AF$22),"") -> 237330 | H22: =IFERROR(IF(0=LEN(ReferenceData!$AE$22),"",ReferenceData!$AE$22),"") -> 249403 | I22: =IFERROR(IF(0=LEN(ReferenceData!$AD$22),"",ReferenceData!$AD$22),"") -> 256712 | J22: =IFERROR(IF(0=LEN(ReferenceData!$AC$22),"",ReferenceData!$AC$22),"") -> 285168 | K22: =IFERROR(IF(0=LEN(ReferenceData!$AB$22),"",ReferenceData!$AB$22),"") -> 317917 | L22: =IFERROR(IF(0=LEN(ReferenceData!$AA$22),"",ReferenceData!$AA$22),"") -> 344167 | M22: =IFERROR(IF(0=LEN(ReferenceData!$Z$22),"",ReferenceData!$Z$22),"") -> 361081 | N22: =IFERROR(IF(0=LEN(ReferenceData!$Y$22),"",ReferenceData!$Y$22),"") -> 407902 | O22: =IFERROR(IF(0=LEN(ReferenceData!$X$22),"",ReferenceData!$X$22),"") -> 428727 | P22: =IFERROR(IF(0=LEN(ReferenceData!$W$22),"",ReferenceData!$W$22),"") -> 491499 | Q22: =IFERROR(IF(0=LEN(ReferenceData!$V$22),"",ReferenceData!$V$22),"") -> 550444 | R22: =IFERROR(IF(0=LEN(ReferenceData!$U$22),"",ReferenceData!$U$22),"") -> 584933 | S22: =IFERROR(IF(0=LEN(ReferenceData!$T$22),"",ReferenceData!$T$22),"") -> 607361 | T22: =IFERROR(IF(0=LEN(ReferenceData!$S$22),"",ReferenceData!$S$22),"") -> 698961 | U22: =IFERROR(IF(0=LEN(ReferenceData!$R$22),"",ReferenceData!$R$22),"") -> 762238 | V22: =IFERROR(IF(0=LEN(ReferenceData!$Q$22),"",ReferenceData!$Q$22),"") -> 798710 | W22: =IFERROR(IF(0=LEN(ReferenceData!$P$22),"",ReferenceData!$P$22),"") -> 885143 | X22: =IFERROR(IF(0=LEN(ReferenceData!$O$22),"",ReferenceData!$O$22),"") -> 952353 | Y22: =IFERROR(IF(0=LEN(ReferenceData!$N$22),"",ReferenceData!$N$22),"") -> 988790 | Z22: =IFERROR(IF(0=LEN(ReferenceData!$M$22),"",ReferenceData!$M$22),"") -> 894269 | AA22: =IFERROR(IF(0=LEN(ReferenceData!$L$22),"",ReferenceData!$L$22),"") -> 873651 | AB22: =IFERROR(IF(0=LEN(ReferenceData!$K$22),"",ReferenceData!$K$22),"") -> 839082 | AC22: =IFERROR(IF(0=LEN(ReferenceData!$J$22),"",ReferenceData!$J$22),"") -> 894646 | AD22: =IFERROR(IF(0=LEN(ReferenceData!$I$22),"",ReferenceData!$I$22),"") -> 923523 | AE22: =IFERROR(IF(0=LEN(ReferenceData!$H$22),"",ReferenceData!$H$22),"") -> 959961 | AF22: =IFERROR(IF(0=LEN(ReferenceData!$G$22),"",ReferenceData!$G$22),"") -> 996272 | AG22: =IFERROR(IF(0=LEN(ReferenceData!$F$22),"",ReferenceData!$F$22),"") -> 1064430
