Workbook

Sheet BIData
A2: =IFERROR(IF(0=LEN(ReferenceData!$A$2),"",ReferenceData!$A$2),"") -> Description | B2: =IFERROR(IF(0=LEN(ReferenceData!$B$2),"",ReferenceData!$B$2),"") -> Ticker | C2: =IFERROR(IF(0=LEN(ReferenceData!$C$2),"",ReferenceData!$C$2),"") -> Field ID | D2: =IFERROR(IF(0=LEN(ReferenceData!$D$2),"",ReferenceData!$D$2),"") -> Field Mnemonic | E2: =IFERROR(IF(0=LEN(ReferenceData!$E$2),"",ReferenceData!$E$2),"") -> Data State | F2: =IFERROR(IF(0=LEN(ReferenceData!$AO$2),"",ReferenceData!$AO$2),"") -> 2017 Q1 | G2: =IFERROR(IF(0=LEN(ReferenceData!$AN$2),"",ReferenceData!$AN$2),"") -> 2017 Q2 | H2: =IFERROR(IF(0=LEN(ReferenceData!$AM$2),"",ReferenceData!$AM$2),"") -> 2017 Q3 | I2: =IFERROR(IF(0=LEN(ReferenceData!$AL$2),"",ReferenceData!$AL$2),"") -> 2017 Q4 | J2: =IFERROR(IF(0=LEN(ReferenceData!$AK$2),"",ReferenceData!$AK$2),"") -> 2018 Q1 | K2: =IFERROR(IF(0=LEN(ReferenceData!$AJ$2),"",ReferenceData!$AJ$2),"") -> 2018 Q2 | L2: =IFERROR(IF(0=LEN(ReferenceData!$AI$2),"",ReferenceData!$AI$2),"") -> 2018 Q3 | M2: =IFERROR(IF(0=LEN(ReferenceData!$AH$2),"",ReferenceData!$AH$2),"") -> 2018 Q4 | N2: =IFERROR(IF(0=LEN(ReferenceData!$AG$2),"",ReferenceData!$AG$2),"") -> 2019 Q1 | O2: =IFERROR(IF(0=LEN(ReferenceData!$AF$2),"",ReferenceData!$AF$2),"") -> 2019 Q2 | P2: =IFERROR(IF(0=LEN(ReferenceData!$AE$2),"",ReferenceData!$AE$2),"") -> 2019 Q3 | Q2: =IFERROR(IF(0=LEN(ReferenceData!$AD$2),"",ReferenceData!$AD$2),"") -> 2019 Q4 | R2: =IFERROR(IF(0=LEN(ReferenceData!$AC$2),"",ReferenceData!$AC$2),"") -> 2020 Q1 | S2: =IFERROR(IF(0=LEN(ReferenceData!$AB$2),"",ReferenceData!$AB$2),"") -> 2020 Q2 | T2: =IFERROR(IF(0=LEN(ReferenceData!$AA$2),"",ReferenceData!$AA$2),"") -> 2020 Q3 | U2: =IFERROR(IF(0=LEN(ReferenceData!$Z$2),"",ReferenceData!$Z$2),"") -> 2020 Q4 | V2: =IFERROR(IF(0=LEN(ReferenceData!$Y$2),"",ReferenceData!$Y$2),"") -> 2021 Q1 | W2: =IFERROR(IF(0=LEN(ReferenceData!$X$2),"",ReferenceData!$X$2),"") -> 2021 Q2 | X2: =IFERROR(IF(0=LEN(ReferenceData!$W$2),"",ReferenceData!$W$2),"") -> 2021 Q3 | Y2: =IFERROR(IF(0=LEN(ReferenceData!$V$2),"",ReferenceData!$V$2),"") -> 2021 Q4 | Z2: =IFERROR(IF(0=LEN(ReferenceData!$U$2),"",ReferenceData!$U$2),"") -> 2022 Q1 | AA2: =IFERROR(IF(0=LEN(ReferenceData!$T$2),"",ReferenceData!$T$2),"") -> 2022 Q2 | AB2: =IFERROR(IF(0=LEN(ReferenceData!$S$2),"",ReferenceData!$S$2),"") -> 2022 Q3 | AC2: =IFERROR(IF(0=LEN(ReferenceData!$R$2),"",ReferenceData!$R$2),"") -> 2022 Q4 | AD2: =IFERROR(IF(0=LEN(ReferenceData!$Q$2),"",ReferenceData!$Q$2),"") -> 2023 Q1 | AE2: =IFERROR(IF(0=LEN(ReferenceData!$P$2),"",ReferenceData!$P$2),"") -> 2023 Q2 | AF2: =IFERROR(IF(0=LEN(ReferenceData!$O$2),"",ReferenceData!$O$2),"") -> 2023 Q3 | AG2: =IFERROR(IF(0=LEN(ReferenceData!$N$2),"",ReferenceData!$N$2),"") -> 2023 Q4 | AH2: =IFERROR(IF(0=LEN(ReferenceData!$M$2),"",ReferenceData!$M$2),"") -> 2024 Q1 | AI2: =IFERROR(IF(0=LEN(ReferenceData!$L$2),"",ReferenceData!$L$2),"") -> 2024 Q2 | AJ2: =IFERROR(IF(0=LEN(ReferenceData!$K$2),"",ReferenceData!$K$2),"") -> 2024 Q3 | AK2: =IFERROR(IF(0=LEN(ReferenceData!$J$2),"",ReferenceData!$J$2),"") -> 2024 Q4 | AL2: =IFERROR(IF(0=LEN(ReferenceData!$I$2),"",ReferenceData!$I$2),"") -> 2025 Q1 | AM2: =IFERROR(IF(0=LEN(ReferenceData!$H$2),"",ReferenceData!$H$2),"") -> 2025 Q2 | AN2: =IFERROR(IF(0=LEN(ReferenceData!$G$2),"",ReferenceData!$G$2),"") -> 2025 Q3 | AO2: =IFERROR(IF(0=LEN(ReferenceData!$F$2),"",ReferenceData!$F$2),"") -> 2025 Q4
A3: =IFERROR(IF(0=LEN(ReferenceData!$A$3),"",ReferenceData!$A$3),"") -> SPX Index Buyback Program Announcements (B$) | B3: =IFERROR(IF(0=LEN(ReferenceData!$B$3),"",ReferenceData!$B$3),"") | C3: =IFERROR(IF(0=LEN(ReferenceData!$C$3),"",ReferenceData!$C$3),"") | D3: =IFERROR(IF(0=LEN(ReferenceData!$D$3),"",ReferenceData!$D$3),"") | E3: =IFERROR(IF(0=LEN(ReferenceData!$E$3),"",ReferenceData!$E$3),"") -> Static | F3: =IFERROR(IF(0=LEN(ReferenceData!$AO$3),"",ReferenceData!$AO$3),"") -> 82.714319 | G3: =IFERROR(IF(0=LEN(ReferenceData!$AN$3),"",ReferenceData!$AN$3),"") -> 207.36028 | H3: =IFERROR(IF(0=LEN(ReferenceData!$AM$3),"",ReferenceData!$AM$3),"") -> 62.861166 | I3: =IFERROR(IF(0=LEN(ReferenceData!$AL$3),"",ReferenceData!$AL$3),"") -> 165.02029 | J3: =IFERROR(IF(0=LEN(ReferenceData!$AK$3),"",ReferenceData!$AK$3),"") -> 187.68782 | K3: =IFERROR(IF(0=LEN(ReferenceData!$AJ$3),"",ReferenceData!$AJ$3),"") -> 417.68612 | L3: =IFERROR(IF(0=LEN(ReferenceData!$AI$3),"",ReferenceData!$AI$3),"") -> 144.2893 | M3: =IFERROR(IF(0=LEN(ReferenceData!$AH$3),"",ReferenceData!$AH$3),"") -> 209.9238 | N3: =IFERROR(IF(0=LEN(ReferenceData!$AG$3),"",ReferenceData!$AG$3),"") -> 214.44461 | O3: =IFERROR(IF(0=LEN(ReferenceData!$AF$3),"",ReferenceData!$AF$3),"") -> 257.74179 | P3: =IFERROR(IF(0=LEN(ReferenceData!$AE$3),"",ReferenceData!$AE$3),"") -> 143.53531 | Q3: =IFERROR(IF(0=LEN(ReferenceData!$AD$3),"",ReferenceData!$AD$3),"") -> 114.1614 | R3: =IFERROR(IF(0=LEN(ReferenceData!$AC$3),"",ReferenceData!$AC$3),"") -> 121.8862 | S3: =IFERROR(IF(0=LEN(ReferenceData!$AB$3),"",ReferenceData!$AB$3),"") -> 59.731739 | T3: =IFERROR(IF(0=LEN(ReferenceData!$AA$3),"",ReferenceData!$AA$3),"") -> 61.605488 | U3: =IFERROR(IF(0=LEN(ReferenceData!$Z$3),"",ReferenceData!$Z$3),"") -> 159.78713 | V3: =IFERROR(IF(0=LEN(ReferenceData!$Y$3),"",ReferenceData!$Y$3),"") -> 246.14246 | W3: =IFERROR(IF(0=LEN(ReferenceData!$X$3),"",ReferenceData!$X$3),"") -> 367.30354 | X3: =IFERROR(IF(0=LEN(ReferenceData!$W$3),"",ReferenceData!$W$3),"") -> 186.63899 | Y3: =IFERROR(IF(0=LEN(ReferenceData!$V$3),"",ReferenceData!$V$3),"") -> 280.48714 | Z3: =IFERROR(IF(0=LEN(ReferenceData!$U$3),"",ReferenceData!$U$3),"") -> 245.46491 | AA3: =IFERROR(IF(0=LEN(ReferenceData!$T$3),"",ReferenceData!$T$3),"") -> 398.74144 | AB3: =IFERROR(IF(0=LEN(ReferenceData!$S$3),"",ReferenceData!$S$3),"") -> 176.00299 | AC3: =IFERROR(IF(0=LEN(ReferenceData!$R$3),"",ReferenceData!$R$3),"") -> 240.62458 | AD3: =IFERROR(IF(0=LEN(ReferenceData!$Q$3),"",ReferenceData!$Q$3),"") -> 315.48766 | AE3: =IFERROR(IF(0=LEN(ReferenceData!$P$3),"",ReferenceData!$P$3),"") -> 252.09484 | AF3: =IFERROR(IF(0=LEN(ReferenceData!$O$3),"",ReferenceData!$O$3),"") -> 148.0682 | AG3: =IFERROR(IF(0=LEN(ReferenceData!$N$3),"",ReferenceData!$N$3),"") -> 197.44256 | AH3: =IFERROR(IF(0=LEN(ReferenceData!$M$3),"",ReferenceData!$M$3),"") -> 261.91253 | AI3: =IFERROR(IF(0=LEN(ReferenceData!$L$3),"",ReferenceData!$L$3),"") -> 352.59508 | AJ3: =IFERROR(IF(0=LEN(ReferenceData!$K$3),"",ReferenceData!$K$3),"") -> 240.0716 | AK3: =IFERROR(IF(0=LEN(ReferenceData!$J$3),"",ReferenceData!$J$3),"") -> 272.7271 | AL3: =IFERROR(IF(0=LEN(ReferenceData!$I$3),"",ReferenceData!$I$3),"") -> 302.50473 | AM3: =IFERROR(IF(0=LEN(ReferenceData!$H$3),"",ReferenceData!$H$3),"") -> 402.81508 | AN3: =IFERROR(IF(0=LEN(ReferenceData!$G$3),"",ReferenceData!$G$3),"") -> 363.3533 | AO3: =IFERROR(IF(0=LEN(ReferenceData!$F$3),"",ReferenceData!$F$3),"") -> 159.9674
A4: =IFERROR(IF(0=LEN(ReferenceData!$A$4),"",ReferenceData!$A$4),"") -> Latest Update: 6/26 | B4: =IFERROR(IF(0=LEN(ReferenceData!$B$4),"",ReferenceData!$B$4),"") | C4: =IFERROR(IF(0=LEN(ReferenceData!$C$4),"",ReferenceData!$C$4),"") | D4: =IFERROR(IF(0=LEN(ReferenceData!$D$4),"",ReferenceData!$D$4),"") | E4: =IFERROR(IF(0=LEN(ReferenceData!$E$4),"",ReferenceData!$E$4),"") -> Static | F4: =IFERROR(IF(0=LEN(ReferenceData!$AO$4),"",ReferenceData!$AO$4),"") | G4: =IFERROR(IF(0=LEN(ReferenceData!$AN$4),"",ReferenceData!$AN$4),"") | H4: =IFERROR(IF(0=LEN(ReferenceData!$AM$4),"",ReferenceData!$AM$4),"") | I4: =IFERROR(IF(0=LEN(ReferenceData!$AL$4),"",ReferenceData!$AL$4),"") | J4: =IFERROR(IF(0=LEN(ReferenceData!$AK$4),"",ReferenceData!$AK$4),"") | K4: =IFERROR(IF(0=LEN(ReferenceData!$AJ$4),"",ReferenceData!$AJ$4),"") | L4: =IFERROR(IF(0=LEN(ReferenceData!$AI$4),"",ReferenceData!$AI$4),"") | M4: =IFERROR(IF(0=LEN(ReferenceData!$AH$4),"",ReferenceData!$AH$4),"") | N4: =IFERROR(IF(0=LEN(ReferenceData!$AG$4),"",ReferenceData!$AG$4),"") | O4: =IFERROR(IF(0=LEN(ReferenceData!$AF$4),"",ReferenceData!$AF$4),"") | P4: =IFERROR(IF(0=LEN(ReferenceData!$AE$4),"",ReferenceData!$AE$4),"") | Q4: =IFERROR(IF(0=LEN(ReferenceData!$AD$4),"",ReferenceData!$AD$4),"") | R4: =IFERROR(IF(0=LEN(ReferenceData!$AC$4),"",ReferenceData!$AC$4),"") | S4: =IFERROR(IF(0=LEN(ReferenceData!$AB$4),"",ReferenceData!$AB$4),"") | T4: =IFERROR(IF(0=LEN(ReferenceData!$AA$4),"",ReferenceData!$AA$4),"") | U4: =IFERROR(IF(0=LEN(ReferenceData!$Z$4),"",ReferenceData!$Z$4),"") | V4: =IFERROR(IF(0=LEN(ReferenceData!$Y$4),"",ReferenceData!$Y$4),"") | W4: =IFERROR(IF(0=LEN(ReferenceData!$X$4),"",ReferenceData!$X$4),"") | X4: =IFERROR(IF(0=LEN(ReferenceData!$W$4),"",ReferenceData!$W$4),"") | Y4: =IFERROR(IF(0=LEN(ReferenceData!$V$4),"",ReferenceData!$V$4),"") | Z4: =IFERROR(IF(0=LEN(ReferenceData!$U$4),"",ReferenceData!$U$4),"") | AA4: =IFERROR(IF(0=LEN(ReferenceData!$T$4),"",ReferenceData!$T$4),"") | AB4: =IFERROR(IF(0=LEN(ReferenceData!$S$4),"",ReferenceData!$S$4),"") | AC4: =IFERROR(IF(0=LEN(ReferenceData!$R$4),"",ReferenceData!$R$4),"") | AD4: =IFERROR(IF(0=LEN(ReferenceData!$Q$4),"",ReferenceData!$Q$4),"") | AE4: =IFERROR(IF(0=LEN(ReferenceData!$P$4),"",ReferenceData!$P$4),"") | AF4: =IFERROR(IF(0=LEN(ReferenceData!$O$4),"",ReferenceData!$O$4),"") | AG4: =IFERROR(IF(0=LEN(ReferenceData!$N$4),"",ReferenceData!$N$4),"") | AH4: =IFERROR(IF(0=LEN(ReferenceData!$M$4),"",ReferenceData!$M$4),"") | AI4: =IFERROR(IF(0=LEN(ReferenceData!$L$4),"",ReferenceData!$L$4),"") | AJ4: =IFERROR(IF(0=LEN(ReferenceData!$K$4),"",ReferenceData!$K$4),"") | AK4: =IFERROR(IF(0=LEN(ReferenceData!$J$4),"",ReferenceData!$J$4),"") | AL4: =IFERROR(IF(0=LEN(ReferenceData!$I$4),"",ReferenceData!$I$4),"") | AM4: =IFERROR(IF(0=LEN(ReferenceData!$H$4),"",ReferenceData!$H$4),"") | AN4: =IFERROR(IF(0=LEN(ReferenceData!$G$4),"",ReferenceData!$G$4),"") | AO4: =IFERROR(IF(0=LEN(ReferenceData!$F$4),"",ReferenceData!$F$4),"")
A5: =IFERROR(IF(0=LEN(ReferenceData!$A$5),"",ReferenceData!$A$5),"") -> Communication Services | B5: =IFERROR(IF(0=LEN(ReferenceData!$B$5),"",ReferenceData!$B$5),"") | C5: =IFERROR(IF(0=LEN(ReferenceData!$C$5),"",ReferenceData!$C$5),"") | D5: =IFERROR(IF(0=LEN(ReferenceData!$D$5),"",ReferenceData!$D$5),"") | E5: =IFERROR(IF(0=LEN(ReferenceData!$E$5),"",ReferenceData!$E$5),"") -> Static | F5: =IFERROR(IF(0=LEN(ReferenceData!$AO$5),"",ReferenceData!$AO$5),"") -> 6.3090012 | G5: =IFERROR(IF(0=LEN(ReferenceData!$AN$5),"",ReferenceData!$AN$5),"") -> 1.2000003 | H5: =IFERROR(IF(0=LEN(ReferenceData!$AM$5),"",ReferenceData!$AM$5),"") | I5: =IFERROR(IF(0=LEN(ReferenceData!$AL$5),"",ReferenceData!$AL$5),"") | J5: =IFERROR(IF(0=LEN(ReferenceData!$AK$5),"",ReferenceData!$AK$5),"") -> 9.1398702 | K5: =IFERROR(IF(0=LEN(ReferenceData!$AJ$5),"",ReferenceData!$AJ$5),"") -> 11.399996 | L5: =IFERROR(IF(0=LEN(ReferenceData!$AI$5),"",ReferenceData!$AI$5),"") | M5: =IFERROR(IF(0=LEN(ReferenceData!$AH$5),"",ReferenceData!$AH$5),"") -> 8.9999954 | N5: =IFERROR(IF(0=LEN(ReferenceData!$AG$5),"",ReferenceData!$AG$5),"") -> 2.7499996 | O5: =IFERROR(IF(0=LEN(ReferenceData!$AF$5),"",ReferenceData!$AF$5),"") | P5: =IFERROR(IF(0=LEN(ReferenceData!$AE$5),"",ReferenceData!$AE$5),"") -> 2.5 | Q5: =IFERROR(IF(0=LEN(ReferenceData!$AD$5),"",ReferenceData!$AD$5),"") -> 2.1000003 | R5: =IFERROR(IF(0=LEN(ReferenceData!$AC$5),"",ReferenceData!$AC$5),"") -> 15.944002 | S5: =IFERROR(IF(0=LEN(ReferenceData!$AB$5),"",ReferenceData!$AB$5),"") | T5: =IFERROR(IF(0=LEN(ReferenceData!$AA$5),"",ReferenceData!$AA$5),"") -> 28 | U5: =IFERROR(IF(0=LEN(ReferenceData!$Z$5),"",ReferenceData!$Z$5),"") -> 2.6000001 | V5: =IFERROR(IF(0=LEN(ReferenceData!$Y$5),"",ReferenceData!$Y$5),"") -> 29 | W5: =IFERROR(IF(0=LEN(ReferenceData!$X$5),"",ReferenceData!$X$5),"") -> 67.000002 | X5: =IFERROR(IF(0=LEN(ReferenceData!$W$5),"",ReferenceData!$W$5),"") -> 2.0000002 | Y5: =IFERROR(IF(0=LEN(ReferenceData!$V$5),"",ReferenceData!$V$5),"") -> 51.36784 | Z5: =IFERROR(IF(0=LEN(ReferenceData!$U$5),"",ReferenceData!$U$5),"") -> 4.0625786 | AA5: =IFERROR(IF(0=LEN(ReferenceData!$T$5),"",ReferenceData!$T$5),"") -> 70.0125 | AB5: =IFERROR(IF(0=LEN(ReferenceData!$S$5),"",ReferenceData!$S$5),"") -> 36.600003 | AC5: =IFERROR(IF(0=LEN(ReferenceData!$R$5),"",ReferenceData!$R$5),"") -> 5.5 | AD5: =IFERROR(IF(0=LEN(ReferenceData!$Q$5),"",ReferenceData!$Q$5),"") -> 43.35 | AE5: =IFERROR(IF(0=LEN(ReferenceData!$P$5),"",ReferenceData!$P$5),"") -> 71 | AF5: =IFERROR(IF(0=LEN(ReferenceData!$O$5),"",ReferenceData!$O$5),"") -> 19 | AG5: =IFERROR(IF(0=LEN(ReferenceData!$N$5),"",ReferenceData!$N$5),"") -> 10 | AH5: =IFERROR(IF(0=LEN(ReferenceData!$M$5),"",ReferenceData!$M$5),"") -> 105.976 | AI5: =IFERROR(IF(0=LEN(ReferenceData!$L$5),"",ReferenceData!$L$5),"") -> 75 | AJ5: =IFERROR(IF(0=LEN(ReferenceData!$K$5),"",ReferenceData!$K$5),"") | AK5: =IFERROR(IF(0=LEN(ReferenceData!$J$5),"",ReferenceData!$J$5),"") -> 15.5 | AL5: =IFERROR(IF(0=LEN(ReferenceData!$I$5),"",ReferenceData!$I$5),"") -> 41.155 | AM5: =IFERROR(IF(0=LEN(ReferenceData!$H$5),"",ReferenceData!$H$5),"") -> 70 | AN5: =IFERROR(IF(0=LEN(ReferenceData!$G$5),"",ReferenceData!$G$5),"") -> 6.8 | AO5: =IFERROR(IF(0=LEN(ReferenceData!$F$5),"",ReferenceData!$F$5),"") -> 2
A6: =IFERROR(IF(0=LEN(ReferenceData!$A$6),"",ReferenceData!$A$6),"") -> Consumer Discretionary | B6: =IFERROR(IF(0=LEN(ReferenceData!$B$6),"",ReferenceData!$B$6),"") | C6: =IFERROR(IF(0=LEN(ReferenceData!$C$6),"",ReferenceData!$C$6),"") | D6: =IFERROR(IF(0=LEN(ReferenceData!$D$6),"",ReferenceData!$D$6),"") | E6: =IFERROR(IF(0=LEN(ReferenceData!$E$6),"",ReferenceData!$E$6),"") -> Static | F6: =IFERROR(IF(0=LEN(ReferenceData!$AO$6),"",ReferenceData!$AO$6),"") -> 39.579597 | G6: =IFERROR(IF(0=LEN(ReferenceData!$AN$6),"",ReferenceData!$AN$6),"") -> 3.2000001 | H6: =IFERROR(IF(0=LEN(ReferenceData!$AM$6),"",ReferenceData!$AM$6),"") -> 23.49005 | I6: =IFERROR(IF(0=LEN(ReferenceData!$AL$6),"",ReferenceData!$AL$6),"") -> 23.164297 | J6: =IFERROR(IF(0=LEN(ReferenceData!$AK$6),"",ReferenceData!$AK$6),"") -> 18.748299 | K6: =IFERROR(IF(0=LEN(ReferenceData!$AJ$6),"",ReferenceData!$AJ$6),"") -> 32.199699 | L6: =IFERROR(IF(0=LEN(ReferenceData!$AI$6),"",ReferenceData!$AI$6),"") -> 5.3500001 | M6: =IFERROR(IF(0=LEN(ReferenceData!$AH$6),"",ReferenceData!$AH$6),"") -> 14.000002 | N6: =IFERROR(IF(0=LEN(ReferenceData!$AG$6),"",ReferenceData!$AG$6),"") -> 38.988898 | O6: =IFERROR(IF(0=LEN(ReferenceData!$AF$6),"",ReferenceData!$AF$6),"") -> 19.6 | P6: =IFERROR(IF(0=LEN(ReferenceData!$AE$6),"",ReferenceData!$AE$6),"") -> 2.5000003 | Q6: =IFERROR(IF(0=LEN(ReferenceData!$AD$6),"",ReferenceData!$AD$6),"") -> 21.861198 | R6: =IFERROR(IF(0=LEN(ReferenceData!$AC$6),"",ReferenceData!$AC$6),"") -> 20.428101 | S6: =IFERROR(IF(0=LEN(ReferenceData!$AB$6),"",ReferenceData!$AB$6),"") | T6: =IFERROR(IF(0=LEN(ReferenceData!$AA$6),"",ReferenceData!$AA$6),"") | U6: =IFERROR(IF(0=LEN(ReferenceData!$Z$6),"",ReferenceData!$Z$6),"") -> 18.3 | V6: =IFERROR(IF(0=LEN(ReferenceData!$Y$6),"",ReferenceData!$Y$6),"") -> 16.168251 | W6: =IFERROR(IF(0=LEN(ReferenceData!$X$6),"",ReferenceData!$X$6),"") -> 31.630719 | X6: =IFERROR(IF(0=LEN(ReferenceData!$W$6),"",ReferenceData!$W$6),"") -> 8.3499988 | Y6: =IFERROR(IF(0=LEN(ReferenceData!$V$6),"",ReferenceData!$V$6),"") -> 21.628 | Z6: =IFERROR(IF(0=LEN(ReferenceData!$U$6),"",ReferenceData!$U$6),"") -> 47.5849 | AA6: =IFERROR(IF(0=LEN(ReferenceData!$T$6),"",ReferenceData!$T$6),"") -> 28.8962 | AB6: =IFERROR(IF(0=LEN(ReferenceData!$S$6),"",ReferenceData!$S$6),"") -> 19.4 | AC6: =IFERROR(IF(0=LEN(ReferenceData!$R$6),"",ReferenceData!$R$6),"") -> 25.649497 | AD6: =IFERROR(IF(0=LEN(ReferenceData!$Q$6),"",ReferenceData!$Q$6),"") -> 24.005003 | AE6: =IFERROR(IF(0=LEN(ReferenceData!$P$6),"",ReferenceData!$P$6),"") -> 7.4136 | AF6: =IFERROR(IF(0=LEN(ReferenceData!$O$6),"",ReferenceData!$O$6),"") -> 15.6 | AG6: =IFERROR(IF(0=LEN(ReferenceData!$N$6),"",ReferenceData!$N$6),"") -> 34.92944 | AH6: =IFERROR(IF(0=LEN(ReferenceData!$M$6),"",ReferenceData!$M$6),"") -> 25.204 | AI6: =IFERROR(IF(0=LEN(ReferenceData!$L$6),"",ReferenceData!$L$6),"") -> 12.0662 | AJ6: =IFERROR(IF(0=LEN(ReferenceData!$K$6),"",ReferenceData!$K$6),"") -> 9.4 | AK6: =IFERROR(IF(0=LEN(ReferenceData!$J$6),"",ReferenceData!$J$6),"") -> 22.65 | AL6: =IFERROR(IF(0=LEN(ReferenceData!$I$6),"",ReferenceData!$I$6),"") -> 48.19078 | AM6: =IFERROR(IF(0=LEN(ReferenceData!$H$6),"",ReferenceData!$H$6),"") -> 15.5 | AN6: =IFERROR(IF(0=LEN(ReferenceData!$G$6),"",ReferenceData!$G$6),"") -> 17.66475 | AO6: =IFERROR(IF(0=LEN(ReferenceData!$F$6),"",ReferenceData!$F$6),"") -> 11.3
A7: =IFERROR(IF(0=LEN(ReferenceData!$A$7),"",ReferenceData!$A$7),"") -> Consumer Staples | B7: =IFERROR(IF(0=LEN(ReferenceData!$B$7),"",ReferenceData!$B$7),"") | C7: =IFERROR(IF(0=LEN(ReferenceData!$C$7),"",ReferenceData!$C$7),"") | D7: =IFERROR(IF(0=LEN(ReferenceData!$D$7),"",ReferenceData!$D$7),"") | E7: =IFERROR(IF(0=LEN(ReferenceData!$E$7),"",ReferenceData!$E$7),"") -> Static | F7: =IFERROR(IF(0=LEN(ReferenceData!$AO$7),"",ReferenceData!$AO$7),"") -> 3.4999999 | G7: =IFERROR(IF(0=LEN(ReferenceData!$AN$7),"",ReferenceData!$AN$7),"") -> 8.0000012 | H7: =IFERROR(IF(0=LEN(ReferenceData!$AM$7),"",ReferenceData!$AM$7),"") -> 1.0000001 | I7: =IFERROR(IF(0=LEN(ReferenceData!$AL$7),"",ReferenceData!$AL$7),"") -> 23.100003 | J7: =IFERROR(IF(0=LEN(ReferenceData!$AK$7),"",ReferenceData!$AK$7),"") -> 27.249998 | K7: =IFERROR(IF(0=LEN(ReferenceData!$AJ$7),"",ReferenceData!$AJ$7),"") -> 19.500003 | L7: =IFERROR(IF(0=LEN(ReferenceData!$AI$7),"",ReferenceData!$AI$7),"") -> 1.2000002 | M7: =IFERROR(IF(0=LEN(ReferenceData!$AH$7),"",ReferenceData!$AH$7),"") -> 5.4976 | N7: =IFERROR(IF(0=LEN(ReferenceData!$AG$7),"",ReferenceData!$AG$7),"") -> 8.379002 | O7: =IFERROR(IF(0=LEN(ReferenceData!$AF$7),"",ReferenceData!$AF$7),"") -> 4 | P7: =IFERROR(IF(0=LEN(ReferenceData!$AE$7),"",ReferenceData!$AE$7),"") -> 12.330002 | Q7: =IFERROR(IF(0=LEN(ReferenceData!$AD$7),"",ReferenceData!$AD$7),"") -> 3.1000004 | R7: =IFERROR(IF(0=LEN(ReferenceData!$AC$7),"",ReferenceData!$AC$7),"") -> 0.50000008 | S7: =IFERROR(IF(0=LEN(ReferenceData!$AB$7),"",ReferenceData!$AB$7),"") | T7: =IFERROR(IF(0=LEN(ReferenceData!$AA$7),"",ReferenceData!$AA$7),"") -> 11.999999 | U7: =IFERROR(IF(0=LEN(ReferenceData!$Z$7),"",ReferenceData!$Z$7),"") -> 4.5781506 | V7: =IFERROR(IF(0=LEN(ReferenceData!$Y$7),"",ReferenceData!$Y$7),"") -> 33.460405 | W7: =IFERROR(IF(0=LEN(ReferenceData!$X$7),"",ReferenceData!$X$7),"") -> 13.750001 | X7: =IFERROR(IF(0=LEN(ReferenceData!$W$7),"",ReferenceData!$W$7),"") -> 26.549998 | Y7: =IFERROR(IF(0=LEN(ReferenceData!$V$7),"",ReferenceData!$V$7),"") -> 6.8648499 | Z7: =IFERROR(IF(0=LEN(ReferenceData!$U$7),"",ReferenceData!$U$7),"") -> 15.2 | AA7: =IFERROR(IF(0=LEN(ReferenceData!$T$7),"",ReferenceData!$T$7),"") -> 7.6040015 | AB7: =IFERROR(IF(0=LEN(ReferenceData!$S$7),"",ReferenceData!$S$7),"") -> 11 | AC7: =IFERROR(IF(0=LEN(ReferenceData!$R$7),"",ReferenceData!$R$7),"") -> 22 | AD7: =IFERROR(IF(0=LEN(ReferenceData!$Q$7),"",ReferenceData!$Q$7),"") -> 10.999998 | AE7: =IFERROR(IF(0=LEN(ReferenceData!$P$7),"",ReferenceData!$P$7),"") -> 1.7 | AF7: =IFERROR(IF(0=LEN(ReferenceData!$O$7),"",ReferenceData!$O$7),"") -> 6 | AG7: =IFERROR(IF(0=LEN(ReferenceData!$N$7),"",ReferenceData!$N$7),"") -> 8.40463 | AH7: =IFERROR(IF(0=LEN(ReferenceData!$M$7),"",ReferenceData!$M$7),"") -> 6.4 | AI7: =IFERROR(IF(0=LEN(ReferenceData!$L$7),"",ReferenceData!$L$7),"") -> 3.5 | AJ7: =IFERROR(IF(0=LEN(ReferenceData!$K$7),"",ReferenceData!$K$7),"") -> 0.5 | AK7: =IFERROR(IF(0=LEN(ReferenceData!$J$7),"",ReferenceData!$J$7),"") -> 22.792 | AL7: =IFERROR(IF(0=LEN(ReferenceData!$I$7),"",ReferenceData!$I$7),"") -> 6 | AM7: =IFERROR(IF(0=LEN(ReferenceData!$H$7),"",ReferenceData!$H$7),"") -> 4 | AN7: =IFERROR(IF(0=LEN(ReferenceData!$G$7),"",ReferenceData!$G$7),"") -> 6.117 | AO7: =IFERROR(IF(0=LEN(ReferenceData!$F$7),"",ReferenceData!$F$7),"") -> 4.4
A8: =IFERROR(IF(0=LEN(ReferenceData!$A$8),"",ReferenceData!$A$8),"") -> Energy | B8: =IFERROR(IF(0=LEN(ReferenceData!$B$8),"",ReferenceData!$B$8),"") | C8: =IFERROR(IF(0=LEN(ReferenceData!$C$8),"",ReferenceData!$C$8),"") | D8: =IFERROR(IF(0=LEN(ReferenceData!$D$8),"",ReferenceData!$D$8),"") | E8: =IFERROR(IF(0=LEN(ReferenceData!$E$8),"",ReferenceData!$E$8),"") -> Static | F8: =IFERROR(IF(0=LEN(ReferenceData!$AO$8),"",ReferenceData!$AO$8),"") -> 2.999999 | G8: =IFERROR(IF(0=LEN(ReferenceData!$AN$8),"",ReferenceData!$AN$8),"") -> 3.4999991 | H8: =IFERROR(IF(0=LEN(ReferenceData!$AM$8),"",ReferenceData!$AM$8),"") -> 2.0000003 | I8: =IFERROR(IF(0=LEN(ReferenceData!$AL$8),"",ReferenceData!$AL$8),"") -> 5.9999981 | J8: =IFERROR(IF(0=LEN(ReferenceData!$AK$8),"",ReferenceData!$AK$8),"") -> 4.7515006 | K8: =IFERROR(IF(0=LEN(ReferenceData!$AJ$8),"",ReferenceData!$AJ$8),"") -> 7.999999 | L8: =IFERROR(IF(0=LEN(ReferenceData!$AI$8),"",ReferenceData!$AI$8),"") -> 10.956196 | M8: =IFERROR(IF(0=LEN(ReferenceData!$AH$8),"",ReferenceData!$AH$8),"") -> 2.8000005 | N8: =IFERROR(IF(0=LEN(ReferenceData!$AG$8),"",ReferenceData!$AG$8),"") -> 25.99999 | O8: =IFERROR(IF(0=LEN(ReferenceData!$AF$8),"",ReferenceData!$AF$8),"") -> 2.0000003 | P8: =IFERROR(IF(0=LEN(ReferenceData!$AE$8),"",ReferenceData!$AE$8),"") -> 1.4289998 | Q8: =IFERROR(IF(0=LEN(ReferenceData!$AD$8),"",ReferenceData!$AD$8),"") -> 3.9999993 | R8: =IFERROR(IF(0=LEN(ReferenceData!$AC$8),"",ReferenceData!$AC$8),"") -> 10.000001 | S8: =IFERROR(IF(0=LEN(ReferenceData!$AB$8),"",ReferenceData!$AB$8),"") | T8: =IFERROR(IF(0=LEN(ReferenceData!$AA$8),"",ReferenceData!$AA$8),"") | U8: =IFERROR(IF(0=LEN(ReferenceData!$Z$8),"",ReferenceData!$Z$8),"") | V8: =IFERROR(IF(0=LEN(ReferenceData!$Y$8),"",ReferenceData!$Y$8),"") | W8: =IFERROR(IF(0=LEN(ReferenceData!$X$8),"",ReferenceData!$X$8),"") -> 8.026615 | X8: =IFERROR(IF(0=LEN(ReferenceData!$W$8),"",ReferenceData!$W$8),"") -> 5.4999999 | Y8: =IFERROR(IF(0=LEN(ReferenceData!$V$8),"",ReferenceData!$V$8),"") -> 8.4399999 | Z8: =IFERROR(IF(0=LEN(ReferenceData!$U$8),"",ReferenceData!$U$8),"") -> 23.850001 | AA8: =IFERROR(IF(0=LEN(ReferenceData!$T$8),"",ReferenceData!$T$8),"") -> 21.760002 | AB8: =IFERROR(IF(0=LEN(ReferenceData!$S$8),"",ReferenceData!$S$8),"") -> 12.0168 | AC8: =IFERROR(IF(0=LEN(ReferenceData!$R$8),"",ReferenceData!$R$8),"") -> 51.300002 | AD8: =IFERROR(IF(0=LEN(ReferenceData!$Q$8),"",ReferenceData!$Q$8),"") -> 89.500009 | AE8: =IFERROR(IF(0=LEN(ReferenceData!$P$8),"",ReferenceData!$P$8),"") -> 11 | AF8: =IFERROR(IF(0=LEN(ReferenceData!$O$8),"",ReferenceData!$O$8),"") -> 2.5 | AG8: =IFERROR(IF(0=LEN(ReferenceData!$N$8),"",ReferenceData!$N$8),"") -> 7.5 | AH8: =IFERROR(IF(0=LEN(ReferenceData!$M$8),"",ReferenceData!$M$8),"") -> 4.5 | AI8: =IFERROR(IF(0=LEN(ReferenceData!$L$8),"",ReferenceData!$L$8),"") -> 5 | AJ8: =IFERROR(IF(0=LEN(ReferenceData!$K$8),"",ReferenceData!$K$8),"") -> 8 | AK8: =IFERROR(IF(0=LEN(ReferenceData!$J$8),"",ReferenceData!$J$8),"") -> 56.2 | AL8: =IFERROR(IF(0=LEN(ReferenceData!$I$8),"",ReferenceData!$I$8),"") | AM8: =IFERROR(IF(0=LEN(ReferenceData!$H$8),"",ReferenceData!$H$8),"") | AN8: =IFERROR(IF(0=LEN(ReferenceData!$G$8),"",ReferenceData!$G$8),"") -> 3 | AO8: =IFERROR(IF(0=LEN(ReferenceData!$F$8),"",ReferenceData!$F$8),"")
A9: =IFERROR(IF(0=LEN(ReferenceData!$A$9),"",ReferenceData!$A$9),"") -> Financials | B9: =IFERROR(IF(0=LEN(ReferenceData!$B$9),"",ReferenceData!$B$9),"") | C9: =IFERROR(IF(0=LEN(ReferenceData!$C$9),"",ReferenceData!$C$9),"") | D9: =IFERROR(IF(0=LEN(ReferenceData!$D$9),"",ReferenceData!$D$9),"") | E9: =IFERROR(IF(0=LEN(ReferenceData!$E$9),"",ReferenceData!$E$9),"") -> Static | F9: =IFERROR(IF(0=LEN(ReferenceData!$AO$9),"",ReferenceData!$AO$9),"") -> 9.7000005 | G9: =IFERROR(IF(0=LEN(ReferenceData!$AN$9),"",ReferenceData!$AN$9),"") -> 118.7575 | H9: =IFERROR(IF(0=LEN(ReferenceData!$AM$9),"",ReferenceData!$AM$9),"") -> 15.003267 | I9: =IFERROR(IF(0=LEN(ReferenceData!$AL$9),"",ReferenceData!$AL$9),"") -> 14.753002 | J9: =IFERROR(IF(0=LEN(ReferenceData!$AK$9),"",ReferenceData!$AK$9),"") -> 36.738095 | K9: =IFERROR(IF(0=LEN(ReferenceData!$AJ$9),"",ReferenceData!$AJ$9),"") -> 128.62568 | L9: =IFERROR(IF(0=LEN(ReferenceData!$AI$9),"",ReferenceData!$AI$9),"") -> 16.842703 | M9: =IFERROR(IF(0=LEN(ReferenceData!$AH$9),"",ReferenceData!$AH$9),"") -> 39.875998 | N9: =IFERROR(IF(0=LEN(ReferenceData!$AG$9),"",ReferenceData!$AG$9),"") -> 25.777221 | O9: =IFERROR(IF(0=LEN(ReferenceData!$AF$9),"",ReferenceData!$AF$9),"") -> 123.94349 | P9: =IFERROR(IF(0=LEN(ReferenceData!$AE$9),"",ReferenceData!$AE$9),"") -> 37.626301 | Q9: =IFERROR(IF(0=LEN(ReferenceData!$AD$9),"",ReferenceData!$AD$9),"") -> 20.600192 | R9: =IFERROR(IF(0=LEN(ReferenceData!$AC$9),"",ReferenceData!$AC$9),"") -> 26.367495 | S9: =IFERROR(IF(0=LEN(ReferenceData!$AB$9),"",ReferenceData!$AB$9),"") -> 6.83176 | T9: =IFERROR(IF(0=LEN(ReferenceData!$AA$9),"",ReferenceData!$AA$9),"") -> 10.754001 | U9: =IFERROR(IF(0=LEN(ReferenceData!$Z$9),"",ReferenceData!$Z$9),"") -> 71.531627 | V9: =IFERROR(IF(0=LEN(ReferenceData!$Y$9),"",ReferenceData!$Y$9),"") -> 57.423477 | W9: =IFERROR(IF(0=LEN(ReferenceData!$X$9),"",ReferenceData!$X$9),"") -> 62.84376 | X9: =IFERROR(IF(0=LEN(ReferenceData!$W$9),"",ReferenceData!$W$9),"") -> 34.989 | Y9: =IFERROR(IF(0=LEN(ReferenceData!$V$9),"",ReferenceData!$V$9),"") -> 57.48305 | Z9: =IFERROR(IF(0=LEN(ReferenceData!$U$9),"",ReferenceData!$U$9),"") -> 24.509997 | AA9: =IFERROR(IF(0=LEN(ReferenceData!$T$9),"",ReferenceData!$T$9),"") -> 104.14759 | AB9: =IFERROR(IF(0=LEN(ReferenceData!$S$9),"",ReferenceData!$S$9),"") -> 26.149996 | AC9: =IFERROR(IF(0=LEN(ReferenceData!$R$9),"",ReferenceData!$R$9),"") -> 32.608581 | AD9: =IFERROR(IF(0=LEN(ReferenceData!$Q$9),"",ReferenceData!$Q$9),"") -> 78.088947 | AE9: =IFERROR(IF(0=LEN(ReferenceData!$P$9),"",ReferenceData!$P$9),"") -> 42.21175 | AF9: =IFERROR(IF(0=LEN(ReferenceData!$O$9),"",ReferenceData!$O$9),"") -> 41.85 | AG9: =IFERROR(IF(0=LEN(ReferenceData!$N$9),"",ReferenceData!$N$9),"") -> 39.821888 | AH9: =IFERROR(IF(0=LEN(ReferenceData!$M$9),"",ReferenceData!$M$9),"") -> 13.658526 | AI9: =IFERROR(IF(0=LEN(ReferenceData!$L$9),"",ReferenceData!$L$9),"") -> 77.149 | AJ9: =IFERROR(IF(0=LEN(ReferenceData!$K$9),"",ReferenceData!$K$9),"") -> 46.5 | AK9: =IFERROR(IF(0=LEN(ReferenceData!$J$9),"",ReferenceData!$J$9),"") -> 35.54574 | AL9: =IFERROR(IF(0=LEN(ReferenceData!$I$9),"",ReferenceData!$I$9),"") -> 80.4066 | AM9: =IFERROR(IF(0=LEN(ReferenceData!$H$9),"",ReferenceData!$H$9),"") -> 138.49675 | AN9: =IFERROR(IF(0=LEN(ReferenceData!$G$9),"",ReferenceData!$G$9),"") -> 147.805 | AO9: =IFERROR(IF(0=LEN(ReferenceData!$F$9),"",ReferenceData!$F$9),"") -> 68.8008
A10: =IFERROR(IF(0=LEN(ReferenceData!$A$10),"",ReferenceData!$A$10),"") -> Health Care | B10: =IFERROR(IF(0=LEN(ReferenceData!$B$10),"",ReferenceData!$B$10),"") | C10: =IFERROR(IF(0=LEN(ReferenceData!$C$10),"",ReferenceData!$C$10),"") | D10: =IFERROR(IF(0=LEN(ReferenceData!$D$10),"",ReferenceData!$D$10),"") | E10: =IFERROR(IF(0=LEN(ReferenceData!$E$10),"",ReferenceData!$E$10),"") -> Static | F10: =IFERROR(IF(0=LEN(ReferenceData!$AO$10),"",ReferenceData!$AO$10),"") -> 7.7499996 | G10: =IFERROR(IF(0=LEN(ReferenceData!$AN$10),"",ReferenceData!$AN$10),"") -> 6.7308411 | H10: =IFERROR(IF(0=LEN(ReferenceData!$AM$10),"",ReferenceData!$AM$10),"") -> 0.40000007 | I10: =IFERROR(IF(0=LEN(ReferenceData!$AL$10),"",ReferenceData!$AL$10),"") -> 29.653004 | J10: =IFERROR(IF(0=LEN(ReferenceData!$AK$10),"",ReferenceData!$AK$10),"") -> 25.000002 | K10: =IFERROR(IF(0=LEN(ReferenceData!$AJ$10),"",ReferenceData!$AJ$10),"") -> 45.965005 | L10: =IFERROR(IF(0=LEN(ReferenceData!$AI$10),"",ReferenceData!$AI$10),"") -> 14.250002 | M10: =IFERROR(IF(0=LEN(ReferenceData!$AH$10),"",ReferenceData!$AH$10),"") -> 44.250005 | N10: =IFERROR(IF(0=LEN(ReferenceData!$AG$10),"",ReferenceData!$AG$10),"") -> 22.8 | O10: =IFERROR(IF(0=LEN(ReferenceData!$AF$10),"",ReferenceData!$AF$10),"") -> 6.0000007 | P10: =IFERROR(IF(0=LEN(ReferenceData!$AE$10),"",ReferenceData!$AE$10),"") -> 5.7000005 | Q10: =IFERROR(IF(0=LEN(ReferenceData!$AD$10),"",ReferenceData!$AD$10),"") -> 20.900001 | R10: =IFERROR(IF(0=LEN(ReferenceData!$AC$10),"",ReferenceData!$AC$10),"") -> 13.416401 | S10: =IFERROR(IF(0=LEN(ReferenceData!$AB$10),"",ReferenceData!$AB$10),"") -> 0.50000008 | T10: =IFERROR(IF(0=LEN(ReferenceData!$AA$10),"",ReferenceData!$AA$10),"") -> 1.3014887 | U10: =IFERROR(IF(0=LEN(ReferenceData!$Z$10),"",ReferenceData!$Z$10),"") -> 16.168655 | V10: =IFERROR(IF(0=LEN(ReferenceData!$Y$10),"",ReferenceData!$Y$10),"") -> 26.899998 | W10: =IFERROR(IF(0=LEN(ReferenceData!$X$10),"",ReferenceData!$X$10),"") -> 10.9 | X10: =IFERROR(IF(0=LEN(ReferenceData!$W$10),"",ReferenceData!$W$10),"") -> 6.9999993 | Y10: =IFERROR(IF(0=LEN(ReferenceData!$V$10),"",ReferenceData!$V$10),"") -> 59.940794 | Z10: =IFERROR(IF(0=LEN(ReferenceData!$U$10),"",ReferenceData!$U$10),"") -> 23.062582 | AA10: =IFERROR(IF(0=LEN(ReferenceData!$T$10),"",ReferenceData!$T$10),"") -> 4 | AB10: =IFERROR(IF(0=LEN(ReferenceData!$S$10),"",ReferenceData!$S$10),"") -> 18.600001 | AC10: =IFERROR(IF(0=LEN(ReferenceData!$R$10),"",ReferenceData!$R$10),"") -> 21.200001 | AD10: =IFERROR(IF(0=LEN(ReferenceData!$Q$10),"",ReferenceData!$Q$10),"") -> 29.399999 | AE10: =IFERROR(IF(0=LEN(ReferenceData!$P$10),"",ReferenceData!$P$10),"") -> 4.6 | AF10: =IFERROR(IF(0=LEN(ReferenceData!$O$10),"",ReferenceData!$O$10),"") -> 13 | AG10: =IFERROR(IF(0=LEN(ReferenceData!$N$10),"",ReferenceData!$N$10),"") -> 25.65 | AH10: =IFERROR(IF(0=LEN(ReferenceData!$M$10),"",ReferenceData!$M$10),"") -> 23.2 | AI10: =IFERROR(IF(0=LEN(ReferenceData!$L$10),"",ReferenceData!$L$10),"") -> 8.672 | AJ10: =IFERROR(IF(0=LEN(ReferenceData!$K$10),"",ReferenceData!$K$10),"") -> 25.0836 | AK10: =IFERROR(IF(0=LEN(ReferenceData!$J$10),"",ReferenceData!$J$10),"") -> 59.081877 | AL10: =IFERROR(IF(0=LEN(ReferenceData!$I$10),"",ReferenceData!$I$10),"") -> 36.0408 | AM10: =IFERROR(IF(0=LEN(ReferenceData!$H$10),"",ReferenceData!$H$10),"") -> 12.75 | AN10: =IFERROR(IF(0=LEN(ReferenceData!$G$10),"",ReferenceData!$G$10),"") -> 17.30155 | AO10: =IFERROR(IF(0=LEN(ReferenceData!$F$10),"",ReferenceData!$F$10),"") -> 16.125
A11: =IFERROR(IF(0=LEN(ReferenceData!$A$11),"",ReferenceData!$A$11),"") -> Industrials | B11: =IFERROR(IF(0=LEN(ReferenceData!$B$11),"",ReferenceData!$B$11),"") | C11: =IFERROR(IF(0=LEN(ReferenceData!$C$11),"",ReferenceData!$C$11),"") | D11: =IFERROR(IF(0=LEN(ReferenceData!$D$11),"",ReferenceData!$D$11),"") | E11: =IFERROR(IF(0=LEN(ReferenceData!$E$11),"",ReferenceData!$E$11),"") -> Static | F11: =IFERROR(IF(0=LEN(ReferenceData!$AO$11),"",ReferenceData!$AO$11),"") -> 4.8241003 | G11: =IFERROR(IF(0=LEN(ReferenceData!$AN$11),"",ReferenceData!$AN$11),"") -> 11.197041 | H11: =IFERROR(IF(0=LEN(ReferenceData!$AM$11),"",ReferenceData!$AM$11),"") -> 11.967852 | I11: =IFERROR(IF(0=LEN(ReferenceData!$AL$11),"",ReferenceData!$AL$11),"") -> 34.149992 | J11: =IFERROR(IF(0=LEN(ReferenceData!$AK$11),"",ReferenceData!$AK$11),"") -> 7.6532001 | K11: =IFERROR(IF(0=LEN(ReferenceData!$AJ$11),"",ReferenceData!$AJ$11),"") -> 11.055182 | L11: =IFERROR(IF(0=LEN(ReferenceData!$AI$11),"",ReferenceData!$AI$11),"") -> 16.200001 | M11: =IFERROR(IF(0=LEN(ReferenceData!$AH$11),"",ReferenceData!$AH$11),"") -> 42.900204 | N11: =IFERROR(IF(0=LEN(ReferenceData!$AG$11),"",ReferenceData!$AG$11),"") -> 44.235506 | O11: =IFERROR(IF(0=LEN(ReferenceData!$AF$11),"",ReferenceData!$AF$11),"") -> 17.995793 | P11: =IFERROR(IF(0=LEN(ReferenceData!$AE$11),"",ReferenceData!$AE$11),"") -> 11 | Q11: =IFERROR(IF(0=LEN(ReferenceData!$AD$11),"",ReferenceData!$AD$11),"") -> 17.000002 | R11: =IFERROR(IF(0=LEN(ReferenceData!$AC$11),"",ReferenceData!$AC$11),"") -> 9.0372015 | S11: =IFERROR(IF(0=LEN(ReferenceData!$AB$11),"",ReferenceData!$AB$11),"") -> 0.7 | T11: =IFERROR(IF(0=LEN(ReferenceData!$AA$11),"",ReferenceData!$AA$11),"") -> 2.3000002 | U11: =IFERROR(IF(0=LEN(ReferenceData!$Z$11),"",ReferenceData!$Z$11),"") -> 16.808701 | V11: =IFERROR(IF(0=LEN(ReferenceData!$Y$11),"",ReferenceData!$Y$11),"") -> 28.52233 | W11: =IFERROR(IF(0=LEN(ReferenceData!$X$11),"",ReferenceData!$X$11),"") -> 11.382701 | X11: =IFERROR(IF(0=LEN(ReferenceData!$W$11),"",ReferenceData!$W$11),"") -> 18.8 | Y11: =IFERROR(IF(0=LEN(ReferenceData!$V$11),"",ReferenceData!$V$11),"") -> 17.012599 | Z11: =IFERROR(IF(0=LEN(ReferenceData!$U$11),"",ReferenceData!$U$11),"") -> 60.589853 | AA11: =IFERROR(IF(0=LEN(ReferenceData!$T$11),"",ReferenceData!$T$11),"") -> 21.268258 | AB11: =IFERROR(IF(0=LEN(ReferenceData!$S$11),"",ReferenceData!$S$11),"") -> 8.4499293 | AC11: =IFERROR(IF(0=LEN(ReferenceData!$R$11),"",ReferenceData!$R$11),"") -> 58.25 | AD11: =IFERROR(IF(0=LEN(ReferenceData!$Q$11),"",ReferenceData!$Q$11),"") -> 8.643701 | AE11: =IFERROR(IF(0=LEN(ReferenceData!$P$11),"",ReferenceData!$P$11),"") -> 10.87537 | AF11: =IFERROR(IF(0=LEN(ReferenceData!$O$11),"",ReferenceData!$O$11),"") -> 11.1782 | AG11: =IFERROR(IF(0=LEN(ReferenceData!$N$11),"",ReferenceData!$N$11),"") -> 31.6466 | AH11: =IFERROR(IF(0=LEN(ReferenceData!$M$11),"",ReferenceData!$M$11),"") -> 36.9324 | AI11: =IFERROR(IF(0=LEN(ReferenceData!$L$11),"",ReferenceData!$L$11),"") -> 27.1416 | AJ11: =IFERROR(IF(0=LEN(ReferenceData!$K$11),"",ReferenceData!$K$11),"") -> 11.3 | AK11: =IFERROR(IF(0=LEN(ReferenceData!$J$11),"",ReferenceData!$J$11),"") -> 25.6766 | AL11: =IFERROR(IF(0=LEN(ReferenceData!$I$11),"",ReferenceData!$I$11),"") -> 17.88655 | AM11: =IFERROR(IF(0=LEN(ReferenceData!$H$11),"",ReferenceData!$H$11),"") -> 18.307542 | AN11: =IFERROR(IF(0=LEN(ReferenceData!$G$11),"",ReferenceData!$G$11),"") -> 66.948 | AO11: =IFERROR(IF(0=LEN(ReferenceData!$F$11),"",ReferenceData!$F$11),"") -> 28.8916
A12: =IFERROR(IF(0=LEN(ReferenceData!$A$12),"",ReferenceData!$A$12),"") -> Information Technology | B12: =IFERROR(IF(0=LEN(ReferenceData!$B$12),"",ReferenceData!$B$12),"") | C12: =IFERROR(IF(0=LEN(ReferenceData!$C$12),"",ReferenceData!$C$12),"") | D12: =IFERROR(IF(0=LEN(ReferenceData!$D$12),"",ReferenceData!$D$12),"") | E12: =IFERROR(IF(0=LEN(ReferenceData!$E$12),"",ReferenceData!$E$12),"") -> Static | F12: =IFERROR(IF(0=LEN(ReferenceData!$AO$12),"",ReferenceData!$AO$12),"") -> 4.5410003 | G12: =IFERROR(IF(0=LEN(ReferenceData!$AN$12),"",ReferenceData!$AN$12),"") -> 45.500002 | H12: =IFERROR(IF(0=LEN(ReferenceData!$AM$12),"",ReferenceData!$AM$12),"") -> 8.9999971 | I12: =IFERROR(IF(0=LEN(ReferenceData!$AL$12),"",ReferenceData!$AL$12),"") -> 24.499995 | J12: =IFERROR(IF(0=LEN(ReferenceData!$AK$12),"",ReferenceData!$AK$12),"") -> 53.856852 | K12: =IFERROR(IF(0=LEN(ReferenceData!$AJ$12),"",ReferenceData!$AJ$12),"") -> 153.49996 | L12: =IFERROR(IF(0=LEN(ReferenceData!$AI$12),"",ReferenceData!$AI$12),"") -> 74.124998 | M12: =IFERROR(IF(0=LEN(ReferenceData!$AH$12),"",ReferenceData!$AH$12),"") -> 44.899994 | N12: =IFERROR(IF(0=LEN(ReferenceData!$AG$12),"",ReferenceData!$AG$12),"") -> 31.924993 | O12: =IFERROR(IF(0=LEN(ReferenceData!$AF$12),"",ReferenceData!$AF$12),"") -> 77.000005 | P12: =IFERROR(IF(0=LEN(ReferenceData!$AE$12),"",ReferenceData!$AE$12),"") -> 68.100004 | Q12: =IFERROR(IF(0=LEN(ReferenceData!$AD$12),"",ReferenceData!$AD$12),"") -> 23.000003 | R12: =IFERROR(IF(0=LEN(ReferenceData!$AC$12),"",ReferenceData!$AC$12),"") -> 25.942996 | S12: =IFERROR(IF(0=LEN(ReferenceData!$AB$12),"",ReferenceData!$AB$12),"") -> 50.699979 | T12: =IFERROR(IF(0=LEN(ReferenceData!$AA$12),"",ReferenceData!$AA$12),"") -> 1.2499998 | U12: =IFERROR(IF(0=LEN(ReferenceData!$Z$12),"",ReferenceData!$Z$12),"") -> 26.749998 | V12: =IFERROR(IF(0=LEN(ReferenceData!$Y$12),"",ReferenceData!$Y$12),"") -> 35.897001 | W12: =IFERROR(IF(0=LEN(ReferenceData!$X$12),"",ReferenceData!$X$12),"") -> 154.94015 | X12: =IFERROR(IF(0=LEN(ReferenceData!$W$12),"",ReferenceData!$W$12),"") -> 77.049989 | Y12: =IFERROR(IF(0=LEN(ReferenceData!$V$12),"",ReferenceData!$V$12),"") -> 40.250003 | Z12: =IFERROR(IF(0=LEN(ReferenceData!$U$12),"",ReferenceData!$U$12),"") -> 33.405 | AA12: =IFERROR(IF(0=LEN(ReferenceData!$T$12),"",ReferenceData!$T$12),"") -> 129.00001 | AB12: =IFERROR(IF(0=LEN(ReferenceData!$S$12),"",ReferenceData!$S$12),"") -> 34.257262 | AC12: =IFERROR(IF(0=LEN(ReferenceData!$R$12),"",ReferenceData!$R$12),"") -> 9.8030003 | AD12: =IFERROR(IF(0=LEN(ReferenceData!$Q$12),"",ReferenceData!$Q$12),"") -> 30.15 | AE12: =IFERROR(IF(0=LEN(ReferenceData!$P$12),"",ReferenceData!$P$12),"") -> 94.500016 | AF12: =IFERROR(IF(0=LEN(ReferenceData!$O$12),"",ReferenceData!$O$12),"") -> 36.94 | AG12: =IFERROR(IF(0=LEN(ReferenceData!$N$12),"",ReferenceData!$N$12),"") -> 21.04 | AH12: =IFERROR(IF(0=LEN(ReferenceData!$M$12),"",ReferenceData!$M$12),"") -> 40.4167 | AI12: =IFERROR(IF(0=LEN(ReferenceData!$L$12),"",ReferenceData!$L$12),"") -> 134.45 | AJ12: =IFERROR(IF(0=LEN(ReferenceData!$K$12),"",ReferenceData!$K$12),"") -> 136.21 | AK12: =IFERROR(IF(0=LEN(ReferenceData!$J$12),"",ReferenceData!$J$12),"") -> 22.780884 | AL12: =IFERROR(IF(0=LEN(ReferenceData!$I$12),"",ReferenceData!$I$12),"") -> 61.75 | AM12: =IFERROR(IF(0=LEN(ReferenceData!$H$12),"",ReferenceData!$H$12),"") -> 136.05 | AN12: =IFERROR(IF(0=LEN(ReferenceData!$G$12),"",ReferenceData!$G$12),"") -> 93.813 | AO12: =IFERROR(IF(0=LEN(ReferenceData!$F$12),"",ReferenceData!$F$12),"") -> 19.7
A13: =IFERROR(IF(0=LEN(ReferenceData!$A$13),"",ReferenceData!$A$13),"") -> Materials | B13: =IFERROR(IF(0=LEN(ReferenceData!$B$13),"",ReferenceData!$B$13),"") | C13: =IFERROR(IF(0=LEN(ReferenceData!$C$13),"",ReferenceData!$C$13),"") | D13: =IFERROR(IF(0=LEN(ReferenceData!$D$13),"",ReferenceData!$D$13),"") | E13: =IFERROR(IF(0=LEN(ReferenceData!$E$13),"",ReferenceData!$E$13),"") -> Static | F13: =IFERROR(IF(0=LEN(ReferenceData!$AO$13),"",ReferenceData!$AO$13),"") -> 2.5106211 | G13: =IFERROR(IF(0=LEN(ReferenceData!$AN$13),"",ReferenceData!$AN$13),"") -> 3.2880974 | H13: =IFERROR(IF(0=LEN(ReferenceData!$AM$13),"",ReferenceData!$AM$13),"") | I13: =IFERROR(IF(0=LEN(ReferenceData!$AL$13),"",ReferenceData!$AL$13),"") -> 6.800001 | J13: =IFERROR(IF(0=LEN(ReferenceData!$AK$13),"",ReferenceData!$AK$13),"") -> 2 | K13: =IFERROR(IF(0=LEN(ReferenceData!$AJ$13),"",ReferenceData!$AJ$13),"") -> 6.9405881 | L13: =IFERROR(IF(0=LEN(ReferenceData!$AI$13),"",ReferenceData!$AI$13),"") -> 2.0000003 | M13: =IFERROR(IF(0=LEN(ReferenceData!$AH$13),"",ReferenceData!$AH$13),"") -> 6.1999996 | N13: =IFERROR(IF(0=LEN(ReferenceData!$AG$13),"",ReferenceData!$AG$13),"") -> 9.5390007 | O13: =IFERROR(IF(0=LEN(ReferenceData!$AF$13),"",ReferenceData!$AF$13),"") -> 7.2024999 | P13: =IFERROR(IF(0=LEN(ReferenceData!$AE$13),"",ReferenceData!$AE$13),"") -> 0.50000008 | Q13: =IFERROR(IF(0=LEN(ReferenceData!$AD$13),"",ReferenceData!$AD$13),"") -> 1.0000002 | R13: =IFERROR(IF(0=LEN(ReferenceData!$AC$13),"",ReferenceData!$AC$13),"") | S13: =IFERROR(IF(0=LEN(ReferenceData!$AB$13),"",ReferenceData!$AB$13),"") | T13: =IFERROR(IF(0=LEN(ReferenceData!$AA$13),"",ReferenceData!$AA$13),"") -> 0.50000007 | U13: =IFERROR(IF(0=LEN(ReferenceData!$Z$13),"",ReferenceData!$Z$13),"") -> 0.15000004 | V13: =IFERROR(IF(0=LEN(ReferenceData!$Y$13),"",ReferenceData!$Y$13),"") -> 18.521 | W13: =IFERROR(IF(0=LEN(ReferenceData!$X$13),"",ReferenceData!$X$13),"") -> 6.829592 | X13: =IFERROR(IF(0=LEN(ReferenceData!$W$13),"",ReferenceData!$W$13),"") -> 4.9000001 | Y13: =IFERROR(IF(0=LEN(ReferenceData!$V$13),"",ReferenceData!$V$13),"") -> 13.000001 | Z13: =IFERROR(IF(0=LEN(ReferenceData!$U$13),"",ReferenceData!$U$13),"") -> 13.2 | AA13: =IFERROR(IF(0=LEN(ReferenceData!$T$13),"",ReferenceData!$T$13),"") -> 10.052875 | AB13: =IFERROR(IF(0=LEN(ReferenceData!$S$13),"",ReferenceData!$S$13),"") -> 6.4000004 | AC13: =IFERROR(IF(0=LEN(ReferenceData!$R$13),"",ReferenceData!$R$13),"") -> 10.813499 | AD13: =IFERROR(IF(0=LEN(ReferenceData!$Q$13),"",ReferenceData!$Q$13),"") -> 0.1 | AE13: =IFERROR(IF(0=LEN(ReferenceData!$P$13),"",ReferenceData!$P$13),"") -> 7.0941001 | AF13: =IFERROR(IF(0=LEN(ReferenceData!$O$13),"",ReferenceData!$O$13),"") -> 2 | AG13: =IFERROR(IF(0=LEN(ReferenceData!$N$13),"",ReferenceData!$N$13),"") -> 16.5 | AH13: =IFERROR(IF(0=LEN(ReferenceData!$M$13),"",ReferenceData!$M$13),"") -> 2.5 | AI13: =IFERROR(IF(0=LEN(ReferenceData!$L$13),"",ReferenceData!$L$13),"") -> 8.6162818 | AJ13: =IFERROR(IF(0=LEN(ReferenceData!$K$13),"",ReferenceData!$K$13),"") -> 1.623 | AK13: =IFERROR(IF(0=LEN(ReferenceData!$J$13),"",ReferenceData!$J$13),"") -> 5 | AL13: =IFERROR(IF(0=LEN(ReferenceData!$I$13),"",ReferenceData!$I$13),"") -> 3.7132 | AM13: =IFERROR(IF(0=LEN(ReferenceData!$H$13),"",ReferenceData!$H$13),"") -> 4.9107915 | AN13: =IFERROR(IF(0=LEN(ReferenceData!$G$13),"",ReferenceData!$G$13),"") -> 3.5 | AO13: =IFERROR(IF(0=LEN(ReferenceData!$F$13),"",ReferenceData!$F$13),"") -> 2
A14: =IFERROR(IF(0=LEN(ReferenceData!$A$14),"",ReferenceData!$A$14),"") -> Real Estate | B14: =IFERROR(IF(0=LEN(ReferenceData!$B$14),"",ReferenceData!$B$14),"") | C14: =IFERROR(IF(0=LEN(ReferenceData!$C$14),"",ReferenceData!$C$14),"") | D14: =IFERROR(IF(0=LEN(ReferenceData!$D$14),"",ReferenceData!$D$14),"") | E14: =IFERROR(IF(0=LEN(ReferenceData!$E$14),"",ReferenceData!$E$14),"") -> Static | F14: =IFERROR(IF(0=LEN(ReferenceData!$AO$14),"",ReferenceData!$AO$14),"") -> 1.0000002 | G14: =IFERROR(IF(0=LEN(ReferenceData!$AN$14),"",ReferenceData!$AN$14),"") | H14: =IFERROR(IF(0=LEN(ReferenceData!$AM$14),"",ReferenceData!$AM$14),"") | I14: =IFERROR(IF(0=LEN(ReferenceData!$AL$14),"",ReferenceData!$AL$14),"") -> 2.9000005 | J14: =IFERROR(IF(0=LEN(ReferenceData!$AK$14),"",ReferenceData!$AK$14),"") -> 1.5500002 | K14: =IFERROR(IF(0=LEN(ReferenceData!$AJ$14),"",ReferenceData!$AJ$14),"") -> 0.50000007 | L14: =IFERROR(IF(0=LEN(ReferenceData!$AI$14),"",ReferenceData!$AI$14),"") | M14: =IFERROR(IF(0=LEN(ReferenceData!$AH$14),"",ReferenceData!$AH$14),"") -> 0.50000007 | N14: =IFERROR(IF(0=LEN(ReferenceData!$AG$14),"",ReferenceData!$AG$14),"") -> 3.0500003 | O14: =IFERROR(IF(0=LEN(ReferenceData!$AF$14),"",ReferenceData!$AF$14),"") | P14: =IFERROR(IF(0=LEN(ReferenceData!$AE$14),"",ReferenceData!$AE$14),"") -> 1.6000002 | Q14: =IFERROR(IF(0=LEN(ReferenceData!$AD$14),"",ReferenceData!$AD$14),"") -> 0.60000007 | R14: =IFERROR(IF(0=LEN(ReferenceData!$AC$14),"",ReferenceData!$AC$14),"") -> 0.25000004 | S14: =IFERROR(IF(0=LEN(ReferenceData!$AB$14),"",ReferenceData!$AB$14),"") -> 1.0000002 | T14: =IFERROR(IF(0=LEN(ReferenceData!$AA$14),"",ReferenceData!$AA$14),"") -> 0.50000008 | U14: =IFERROR(IF(0=LEN(ReferenceData!$Z$14),"",ReferenceData!$Z$14),"") -> 1.9000001 | V14: =IFERROR(IF(0=LEN(ReferenceData!$Y$14),"",ReferenceData!$Y$14),"") -> 0.25000004 | W14: =IFERROR(IF(0=LEN(ReferenceData!$X$14),"",ReferenceData!$X$14),"") | X14: =IFERROR(IF(0=LEN(ReferenceData!$W$14),"",ReferenceData!$W$14),"") -> 1 | Y14: =IFERROR(IF(0=LEN(ReferenceData!$V$14),"",ReferenceData!$V$14),"") -> 3.0000005 | Z14: =IFERROR(IF(0=LEN(ReferenceData!$U$14),"",ReferenceData!$U$14),"") | AA14: =IFERROR(IF(0=LEN(ReferenceData!$T$14),"",ReferenceData!$T$14),"") -> 2 | AB14: =IFERROR(IF(0=LEN(ReferenceData!$S$14),"",ReferenceData!$S$14),"") -> 3.1290003 | AC14: =IFERROR(IF(0=LEN(ReferenceData!$R$14),"",ReferenceData!$R$14),"") -> 3.5 | AD14: =IFERROR(IF(0=LEN(ReferenceData!$Q$14),"",ReferenceData!$Q$14),"") -> 0.25 | AE14: =IFERROR(IF(0=LEN(ReferenceData!$P$14),"",ReferenceData!$P$14),"") | AF14: =IFERROR(IF(0=LEN(ReferenceData!$O$14),"",ReferenceData!$O$14),"") | AG14: =IFERROR(IF(0=LEN(ReferenceData!$N$14),"",ReferenceData!$N$14),"") | AH14: =IFERROR(IF(0=LEN(ReferenceData!$M$14),"",ReferenceData!$M$14),"") -> 2.7709 | AI14: =IFERROR(IF(0=LEN(ReferenceData!$L$14),"",ReferenceData!$L$14),"") | AJ14: =IFERROR(IF(0=LEN(ReferenceData!$K$14),"",ReferenceData!$K$14),"") -> 0.75 | AK14: =IFERROR(IF(0=LEN(ReferenceData!$J$14),"",ReferenceData!$J$14),"") -> 5.5 | AL14: =IFERROR(IF(0=LEN(ReferenceData!$I$14),"",ReferenceData!$I$14),"") -> 5.5 | AM14: =IFERROR(IF(0=LEN(ReferenceData!$H$14),"",ReferenceData!$H$14),"") -> 2.8 | AN14: =IFERROR(IF(0=LEN(ReferenceData!$G$14),"",ReferenceData!$G$14),"") | AO14: =IFERROR(IF(0=LEN(ReferenceData!$F$14),"",ReferenceData!$F$14),"") -> 2.75
A15: =IFERROR(IF(0=LEN(ReferenceData!$A$15),"",ReferenceData!$A$15),"") -> Utilities | B15: =IFERROR(IF(0=LEN(ReferenceData!$B$15),"",ReferenceData!$B$15),"") | C15: =IFERROR(IF(0=LEN(ReferenceData!$C$15),"",ReferenceData!$C$15),"") | D15: =IFERROR(IF(0=LEN(ReferenceData!$D$15),"",ReferenceData!$D$15),"") | E15: =IFERROR(IF(0=LEN(ReferenceData!$E$15),"",ReferenceData!$E$15),"") -> Static | F15: =IFERROR(IF(0=LEN(ReferenceData!$AO$15),"",ReferenceData!$AO$15),"") | G15: =IFERROR(IF(0=LEN(ReferenceData!$AN$15),"",ReferenceData!$AN$15),"") -> 5.9868013 | H15: =IFERROR(IF(0=LEN(ReferenceData!$AM$15),"",ReferenceData!$AM$15),"") | I15: =IFERROR(IF(0=LEN(ReferenceData!$AL$15),"",ReferenceData!$AL$15),"") | J15: =IFERROR(IF(0=LEN(ReferenceData!$AK$15),"",ReferenceData!$AK$15),"") -> 1.0000002 | K15: =IFERROR(IF(0=LEN(ReferenceData!$AJ$15),"",ReferenceData!$AJ$15),"") | L15: =IFERROR(IF(0=LEN(ReferenceData!$AI$15),"",ReferenceData!$AI$15),"") -> 3.3654 | M15: =IFERROR(IF(0=LEN(ReferenceData!$AH$15),"",ReferenceData!$AH$15),"") | N15: =IFERROR(IF(0=LEN(ReferenceData!$AG$15),"",ReferenceData!$AG$15),"") -> 1.0000001 | O15: =IFERROR(IF(0=LEN(ReferenceData!$AF$15),"",ReferenceData!$AF$15),"") | P15: =IFERROR(IF(0=LEN(ReferenceData!$AE$15),"",ReferenceData!$AE$15),"") -> 0.25000003 | Q15: =IFERROR(IF(0=LEN(ReferenceData!$AD$15),"",ReferenceData!$AD$15),"") | R15: =IFERROR(IF(0=LEN(ReferenceData!$AC$15),"",ReferenceData!$AC$15),"") | S15: =IFERROR(IF(0=LEN(ReferenceData!$AB$15),"",ReferenceData!$AB$15),"") | T15: =IFERROR(IF(0=LEN(ReferenceData!$AA$15),"",ReferenceData!$AA$15),"") -> 4.9999994 | U15: =IFERROR(IF(0=LEN(ReferenceData!$Z$15),"",ReferenceData!$Z$15),"") -> 1.0000001 | V15: =IFERROR(IF(0=LEN(ReferenceData!$Y$15),"",ReferenceData!$Y$15),"") | W15: =IFERROR(IF(0=LEN(ReferenceData!$X$15),"",ReferenceData!$X$15),"") | X15: =IFERROR(IF(0=LEN(ReferenceData!$W$15),"",ReferenceData!$W$15),"") -> 0.50000008 | Y15: =IFERROR(IF(0=LEN(ReferenceData!$V$15),"",ReferenceData!$V$15),"") -> 1.5 | Z15: =IFERROR(IF(0=LEN(ReferenceData!$U$15),"",ReferenceData!$U$15),"") | AA15: =IFERROR(IF(0=LEN(ReferenceData!$T$15),"",ReferenceData!$T$15),"") | AB15: =IFERROR(IF(0=LEN(ReferenceData!$S$15),"",ReferenceData!$S$15),"") | AC15: =IFERROR(IF(0=LEN(ReferenceData!$R$15),"",ReferenceData!$R$15),"") | AD15: =IFERROR(IF(0=LEN(ReferenceData!$Q$15),"",ReferenceData!$Q$15),"") -> 1 | AE15: =IFERROR(IF(0=LEN(ReferenceData!$P$15),"",ReferenceData!$P$15),"") -> 1.7 | AF15: =IFERROR(IF(0=LEN(ReferenceData!$O$15),"",ReferenceData!$O$15),"") | AG15: =IFERROR(IF(0=LEN(ReferenceData!$N$15),"",ReferenceData!$N$15),"") -> 1.95 | AH15: =IFERROR(IF(0=LEN(ReferenceData!$M$15),"",ReferenceData!$M$15),"") -> 0.354 | AI15: =IFERROR(IF(0=LEN(ReferenceData!$L$15),"",ReferenceData!$L$15),"") -> 1 | AJ15: =IFERROR(IF(0=LEN(ReferenceData!$K$15),"",ReferenceData!$K$15),"") -> 0.705 | AK15: =IFERROR(IF(0=LEN(ReferenceData!$J$15),"",ReferenceData!$J$15),"") -> 2 | AL15: =IFERROR(IF(0=LEN(ReferenceData!$I$15),"",ReferenceData!$I$15),"") -> 0.075 | AM15: =IFERROR(IF(0=LEN(ReferenceData!$H$15),"",ReferenceData!$H$15),"") | AN15: =IFERROR(IF(0=LEN(ReferenceData!$G$15),"",ReferenceData!$G$15),"") -> 0.404 | AO15: =IFERROR(IF(0=LEN(ReferenceData!$F$15),"",ReferenceData!$F$15),"") -> 4
A16: =IFERROR(IF(0=LEN(ReferenceData!$A$16),"",ReferenceData!$A$16),"") -> Buyback Program Announcements | B16: =IFERROR(IF(0=LEN(ReferenceData!$B$16),"",ReferenceData!$B$16),"") | C16: =IFERROR(IF(0=LEN(ReferenceData!$C$16),"",ReferenceData!$C$16),"") | D16: =IFERROR(IF(0=LEN(ReferenceData!$D$16),"",ReferenceData!$D$16),"") | E16: =IFERROR(IF(0=LEN(ReferenceData!$E$16),"",ReferenceData!$E$16),"") -> Static | F16: =IFERROR(IF(0=LEN(ReferenceData!$AO$16),"",ReferenceData!$AO$16),"") -> 41 | G16: =IFERROR(IF(0=LEN(ReferenceData!$AN$16),"",ReferenceData!$AN$16),"") -> 55 | H16: =IFERROR(IF(0=LEN(ReferenceData!$AM$16),"",ReferenceData!$AM$16),"") -> 27 | I16: =IFERROR(IF(0=LEN(ReferenceData!$AL$16),"",ReferenceData!$AL$16),"") -> 50 | J16: =IFERROR(IF(0=LEN(ReferenceData!$AK$16),"",ReferenceData!$AK$16),"") -> 64 | K16: =IFERROR(IF(0=LEN(ReferenceData!$AJ$16),"",ReferenceData!$AJ$16),"") -> 80 | L16: =IFERROR(IF(0=LEN(ReferenceData!$AI$16),"",ReferenceData!$AI$16),"") -> 42 | M16: =IFERROR(IF(0=LEN(ReferenceData!$AH$16),"",ReferenceData!$AH$16),"") -> 63 | N16: =IFERROR(IF(0=LEN(ReferenceData!$AG$16),"",ReferenceData!$AG$16),"") -> 65 | O16: =IFERROR(IF(0=LEN(ReferenceData!$AF$16),"",ReferenceData!$AF$16),"") -> 41 | P16: =IFERROR(IF(0=LEN(ReferenceData!$AE$16),"",ReferenceData!$AE$16),"") -> 42 | Q16: =IFERROR(IF(0=LEN(ReferenceData!$AD$16),"",ReferenceData!$AD$16),"") -> 47 | R16: =IFERROR(IF(0=LEN(ReferenceData!$AC$16),"",ReferenceData!$AC$16),"") -> 44 | S16: =IFERROR(IF(0=LEN(ReferenceData!$AB$16),"",ReferenceData!$AB$16),"") -> 8 | T16: =IFERROR(IF(0=LEN(ReferenceData!$AA$16),"",ReferenceData!$AA$16),"") -> 18 | U16: =IFERROR(IF(0=LEN(ReferenceData!$Z$16),"",ReferenceData!$Z$16),"") -> 49 | V16: =IFERROR(IF(0=LEN(ReferenceData!$Y$16),"",ReferenceData!$Y$16),"") -> 73 | W16: =IFERROR(IF(0=LEN(ReferenceData!$X$16),"",ReferenceData!$X$16),"") -> 62 | X16: =IFERROR(IF(0=LEN(ReferenceData!$W$16),"",ReferenceData!$W$16),"") -> 62 | Y16: =IFERROR(IF(0=LEN(ReferenceData!$V$16),"",ReferenceData!$V$16),"") -> 70 | Z16: =IFERROR(IF(0=LEN(ReferenceData!$U$16),"",ReferenceData!$U$16),"") -> 82 | AA16: =IFERROR(IF(0=LEN(ReferenceData!$T$16),"",ReferenceData!$T$16),"") -> 57 | AB16: =IFERROR(IF(0=LEN(ReferenceData!$S$16),"",ReferenceData!$S$16),"") -> 54 | AC16: =IFERROR(IF(0=LEN(ReferenceData!$R$16),"",ReferenceData!$R$16),"") -> 55 | AD16: =IFERROR(IF(0=LEN(ReferenceData!$Q$16),"",ReferenceData!$Q$16),"") -> 59 | AE16: =IFERROR(IF(0=LEN(ReferenceData!$P$16),"",ReferenceData!$P$16),"") -> 37 | AF16: =IFERROR(IF(0=LEN(ReferenceData!$O$16),"",ReferenceData!$O$16),"") -> 29 | AG16: =IFERROR(IF(0=LEN(ReferenceData!$N$16),"",ReferenceData!$N$16),"") -> 58 | AH16: =IFERROR(IF(0=LEN(ReferenceData!$M$16),"",ReferenceData!$M$16),"") -> 72 | AI16: =IFERROR(IF(0=LEN(ReferenceData!$L$16),"",ReferenceData!$L$16),"") -> 49 | AJ16: =IFERROR(IF(0=LEN(ReferenceData!$K$16),"",ReferenceData!$K$16),"") -> 61 | AK16: =IFERROR(IF(0=LEN(ReferenceData!$J$16),"",ReferenceData!$J$16),"") -> 77 | AL16: =IFERROR(IF(0=LEN(ReferenceData!$I$16),"",ReferenceData!$I$16),"") -> 68 | AM16: =IFERROR(IF(0=LEN(ReferenceData!$H$16),"",ReferenceData!$H$16),"") -> 63 | AN16: =IFERROR(IF(0=LEN(ReferenceData!$G$16),"",ReferenceData!$G$16),"") -> 57 | AO16: =IFERROR(IF(0=LEN(ReferenceData!$F$16),"",ReferenceData!$F$16),"") -> 68
A17: =IFERROR(IF(0=LEN(ReferenceData!$A$17),"",ReferenceData!$A$17),"") -> Increased | B17: =IFERROR(IF(0=LEN(ReferenceData!$B$17),"",ReferenceData!$B$17),"") | C17: =IFERROR(IF(0=LEN(ReferenceData!$C$17),"",ReferenceData!$C$17),"") | D17: =IFERROR(IF(0=LEN(ReferenceData!$D$17),"",ReferenceData!$D$17),"") | E17: =IFERROR(IF(0=LEN(ReferenceData!$E$17),"",ReferenceData!$E$17),"") -> Static | F17: =IFERROR(IF(0=LEN(ReferenceData!$AO$17),"",ReferenceData!$AO$17),"") | G17: =IFERROR(IF(0=LEN(ReferenceData!$AN$17),"",ReferenceData!$AN$17),"") -> 2 | H17: =IFERROR(IF(0=LEN(ReferenceData!$AM$17),"",ReferenceData!$AM$17),"") | I17: =IFERROR(IF(0=LEN(ReferenceData!$AL$17),"",ReferenceData!$AL$17),"") -> 4 | J17: =IFERROR(IF(0=LEN(ReferenceData!$AK$17),"",ReferenceData!$AK$17),"") -> 11 | K17: =IFERROR(IF(0=LEN(ReferenceData!$AJ$17),"",ReferenceData!$AJ$17),"") -> 26 | L17: =IFERROR(IF(0=LEN(ReferenceData!$AI$17),"",ReferenceData!$AI$17),"") -> 15 | M17: =IFERROR(IF(0=LEN(ReferenceData!$AH$17),"",ReferenceData!$AH$17),"") -> 20 | N17: =IFERROR(IF(0=LEN(ReferenceData!$AG$17),"",ReferenceData!$AG$17),"") -> 19 | O17: =IFERROR(IF(0=LEN(ReferenceData!$AF$17),"",ReferenceData!$AF$17),"") -> 15 | P17: =IFERROR(IF(0=LEN(ReferenceData!$AE$17),"",ReferenceData!$AE$17),"") -> 12 | Q17: =IFERROR(IF(0=LEN(ReferenceData!$AD$17),"",ReferenceData!$AD$17),"") -> 16 | R17: =IFERROR(IF(0=LEN(ReferenceData!$AC$17),"",ReferenceData!$AC$17),"") -> 19 | S17: =IFERROR(IF(0=LEN(ReferenceData!$AB$17),"",ReferenceData!$AB$17),"") -> 2 | T17: =IFERROR(IF(0=LEN(ReferenceData!$AA$17),"",ReferenceData!$AA$17),"") -> 6 | U17: =IFERROR(IF(0=LEN(ReferenceData!$Z$17),"",ReferenceData!$Z$17),"") -> 22 | V17: =IFERROR(IF(0=LEN(ReferenceData!$Y$17),"",ReferenceData!$Y$17),"") -> 22 | W17: =IFERROR(IF(0=LEN(ReferenceData!$X$17),"",ReferenceData!$X$17),"") -> 33 | X17: =IFERROR(IF(0=LEN(ReferenceData!$W$17),"",ReferenceData!$W$17),"") -> 34 | Y17: =IFERROR(IF(0=LEN(ReferenceData!$V$17),"",ReferenceData!$V$17),"") -> 45 | Z17: =IFERROR(IF(0=LEN(ReferenceData!$U$17),"",ReferenceData!$U$17),"") -> 39 | AA17: =IFERROR(IF(0=LEN(ReferenceData!$T$17),"",ReferenceData!$T$17),"") -> 25 | AB17: =IFERROR(IF(0=LEN(ReferenceData!$S$17),"",ReferenceData!$S$17),"") -> 20 | AC17: =IFERROR(IF(0=LEN(ReferenceData!$R$17),"",ReferenceData!$R$17),"") -> 26 | AD17: =IFERROR(IF(0=LEN(ReferenceData!$Q$17),"",ReferenceData!$Q$17),"") -> 22 | AE17: =IFERROR(IF(0=LEN(ReferenceData!$P$17),"",ReferenceData!$P$17),"") -> 15 | AF17: =IFERROR(IF(0=LEN(ReferenceData!$O$17),"",ReferenceData!$O$17),"") -> 16 | AG17: =IFERROR(IF(0=LEN(ReferenceData!$N$17),"",ReferenceData!$N$17),"") -> 26 | AH17: =IFERROR(IF(0=LEN(ReferenceData!$M$17),"",ReferenceData!$M$17),"") -> 21 | AI17: =IFERROR(IF(0=LEN(ReferenceData!$L$17),"",ReferenceData!$L$17),"") -> 19 | AJ17: =IFERROR(IF(0=LEN(ReferenceData!$K$17),"",ReferenceData!$K$17),"") -> 27 | AK17: =IFERROR(IF(0=LEN(ReferenceData!$J$17),"",ReferenceData!$J$17),"") -> 39 | AL17: =IFERROR(IF(0=LEN(ReferenceData!$I$17),"",ReferenceData!$I$17),"") -> 20 | AM17: =IFERROR(IF(0=LEN(ReferenceData!$H$17),"",ReferenceData!$H$17),"") -> 28 | AN17: =IFERROR(IF(0=LEN(ReferenceData!$G$17),"",ReferenceData!$G$17),"") -> 30 | AO17: =IFERROR(IF(0=LEN(ReferenceData!$F$17),"",ReferenceData!$F$17),"") -> 32
A18: =IFERROR(IF(0=LEN(ReferenceData!$A$18),"",ReferenceData!$A$18),"") -> Decreased | B18: =IFERROR(IF(0=LEN(ReferenceData!$B$18),"",ReferenceData!$B$18),"") | C18: =IFERROR(IF(0=LEN(ReferenceData!$C$18),"",ReferenceData!$C$18),"") | D18: =IFERROR(IF(0=LEN(ReferenceData!$D$18),"",ReferenceData!$D$18),"") | E18: =IFERROR(IF(0=LEN(ReferenceData!$E$18),"",ReferenceData!$E$18),"") -> Static | F18: =IFERROR(IF(0=LEN(ReferenceData!$AO$18),"",ReferenceData!$AO$18),"") | G18: =IFERROR(IF(0=LEN(ReferenceData!$AN$18),"",ReferenceData!$AN$18),"") -> 1 | H18: =IFERROR(IF(0=LEN(ReferenceData!$AM$18),"",ReferenceData!$AM$18),"") -> 2 | I18: =IFERROR(IF(0=LEN(ReferenceData!$AL$18),"",ReferenceData!$AL$18),"") -> 4 | J18: =IFERROR(IF(0=LEN(ReferenceData!$AK$18),"",ReferenceData!$AK$18),"") -> 7 | K18: =IFERROR(IF(0=LEN(ReferenceData!$AJ$18),"",ReferenceData!$AJ$18),"") -> 16 | L18: =IFERROR(IF(0=LEN(ReferenceData!$AI$18),"",ReferenceData!$AI$18),"") -> 4 | M18: =IFERROR(IF(0=LEN(ReferenceData!$AH$18),"",ReferenceData!$AH$18),"") -> 11 | N18: =IFERROR(IF(0=LEN(ReferenceData!$AG$18),"",ReferenceData!$AG$18),"") -> 17 | O18: =IFERROR(IF(0=LEN(ReferenceData!$AF$18),"",ReferenceData!$AF$18),"") -> 10 | P18: =IFERROR(IF(0=LEN(ReferenceData!$AE$18),"",ReferenceData!$AE$18),"") -> 15 | Q18: =IFERROR(IF(0=LEN(ReferenceData!$AD$18),"",ReferenceData!$AD$18),"") -> 11 | R18: =IFERROR(IF(0=LEN(ReferenceData!$AC$18),"",ReferenceData!$AC$18),"") -> 9 | S18: =IFERROR(IF(0=LEN(ReferenceData!$AB$18),"",ReferenceData!$AB$18),"") -> 2 | T18: =IFERROR(IF(0=LEN(ReferenceData!$AA$18),"",ReferenceData!$AA$18),"") -> 5 | U18: =IFERROR(IF(0=LEN(ReferenceData!$Z$18),"",ReferenceData!$Z$18),"") -> 14 | V18: =IFERROR(IF(0=LEN(ReferenceData!$Y$18),"",ReferenceData!$Y$18),"") -> 28 | W18: =IFERROR(IF(0=LEN(ReferenceData!$X$18),"",ReferenceData!$X$18),"") -> 13 | X18: =IFERROR(IF(0=LEN(ReferenceData!$W$18),"",ReferenceData!$W$18),"") -> 9 | Y18: =IFERROR(IF(0=LEN(ReferenceData!$V$18),"",ReferenceData!$V$18),"") -> 10 | Z18: =IFERROR(IF(0=LEN(ReferenceData!$U$18),"",ReferenceData!$U$18),"") -> 27 | AA18: =IFERROR(IF(0=LEN(ReferenceData!$T$18),"",ReferenceData!$T$18),"") -> 14 | AB18: =IFERROR(IF(0=LEN(ReferenceData!$S$18),"",ReferenceData!$S$18),"") -> 16 | AC18: =IFERROR(IF(0=LEN(ReferenceData!$R$18),"",ReferenceData!$R$18),"") -> 15 | AD18: =IFERROR(IF(0=LEN(ReferenceData!$Q$18),"",ReferenceData!$Q$18),"") -> 20 | AE18: =IFERROR(IF(0=LEN(ReferenceData!$P$18),"",ReferenceData!$P$18),"") -> 11 | AF18: =IFERROR(IF(0=LEN(ReferenceData!$O$18),"",ReferenceData!$O$18),"") -> 9 | AG18: =IFERROR(IF(0=LEN(ReferenceData!$N$18),"",ReferenceData!$N$18),"") -> 15 | AH18: =IFERROR(IF(0=LEN(ReferenceData!$M$18),"",ReferenceData!$M$18),"") -> 30 | AI18: =IFERROR(IF(0=LEN(ReferenceData!$L$18),"",ReferenceData!$L$18),"") -> 15 | AJ18: =IFERROR(IF(0=LEN(ReferenceData!$K$18),"",ReferenceData!$K$18),"") -> 13 | AK18: =IFERROR(IF(0=LEN(ReferenceData!$J$18),"",ReferenceData!$J$18),"") -> 14 | AL18: =IFERROR(IF(0=LEN(ReferenceData!$I$18),"",ReferenceData!$I$18),"") -> 25 | AM18: =IFERROR(IF(0=LEN(ReferenceData!$H$18),"",ReferenceData!$H$18),"") -> 10 | AN18: =IFERROR(IF(0=LEN(ReferenceData!$G$18),"",ReferenceData!$G$18),"") -> 13 | AO18: =IFERROR(IF(0=LEN(ReferenceData!$F$18),"",ReferenceData!$F$18),"") -> 12
